Workbook

Sheet ROP 2024
B1: TVM PR & IC KW | D1: MARKET PLAN | G1: YEARS until 2018 | H1: YEAR 2017 | I1: 42370 | J1: 42401 | K1: 42430 | L1: 42461 | M1: 42491 | N1: 42522 | O1: 42552 | P1: 42583 | Q1: 42614 | R1: 42644 | S1: 42675 | T1: 42705 | U1: 2017 YEAR TO DATE | W1: TOTAL ACTUAL
B4: SALES OF TICKETS PR *) | D4: 82265384 | G4: 72392298 | H4: 16387948 | V4: =SUM(I4:T4) -> 0 | W4: =V4+G4+H4 -> 88780245
B5: SALES LEASE AGREEMENT / OTHER SALES | D5: 1485687.9 | G5: 1555442.1 | H5: 0 | V5: =SUM(I5:T5) -> 0 | W5: =V5+G5+H5 -> 1555442.1
B6: IC PROVISION | D6: 4126711 | G6: 2696236.7 | H6: 848927.59 | V6: =SUM(I6:T6) -> 0 | W6: =V6+G6+H6 -> 3545164.3
B7: SALES OF TICKETS KW *) | G7: 8791465.6 | H7: 2796298.5 | V7: =SUM(I7:T7) -> 0 | W7: =V7+G7+H7 -> 11587764
B8: SALES OF ARRIVA RP (FLAT FEE / TVM) | G8: 142480.79 | H8: 19171.89 | V8: =SUM(I8:T8) -> 0 | W8: =V8+G8+H8 -> 161652.68
B9: SALES LEASE AGREEMENT / OTHER SALES
B10: SALES, GROSS | D10: 87877783 | G10: =SUM(G4:G9) -> 85577923 | H10: =SUM(H4:H9) -> 20052346 | V10: =SUM(V4:V9) -> 0 | W10: =SUM(W4:W9) -> 1.0563027e+08
B12: PURCHASE COSTS OF TICKETS PR **) | D12: 72539556 | G12: 61293730 | H12: 13830056 | V12: =SUM(I12:T12) -> 0 | W12: =V12+G12+H12 -> 75123786
B13: PURCHASE COSTS OF TICKETS KW **) | G13: 8100569.3 | H13: 2583838.1 | V13: =SUM(I13:T13) -> 0 | W13: =V13+G13+H13 -> 10684407
B14: SALES, NET | D14: 15338227 | G14: =(G10-G12-G13) -> 16183624 | H14: =(H10-H12-H13) -> 3638451.3 | V14: =(V10-V12-V13) -> 0 | W14: =(W10-W12-W13) -> 19822075
B15: Margin | D15: 0.17454044 | G15: =IF(G10<>0,G14/G10,"") -> 0.1891098 | H15: =IF(H10<>0,H14/H10,"") -> 0.18144767 | V15: =IF(V10<>0,V14/V10,"") | W15: =IF(W10<>0,W14/W10,"") -> 0.18765526
B17: DEPRECIATION (8 years, of initial investment, calculatory) | D17: 4982793 | G17: 3507538.9 | H17: 578795.52 | V17: =SUM(I17:T17) -> 0 | W17: =V17+G17+H17 -> 4086334.4
D18: 0 | G18: 0 | H18: 0 | V18: =SUM(I18:T18) -> 0 | W18: =V18+G18 -> 0
B19: MATERIAL & EQUIPMENT | D19: 379002 | G19: 364470.01 | H19: 97555.27 | V19: =SUM(I19:T19) -> 0 | W19: =V19+G19+H19 -> 462025.28
B20: thereof internal | D20: 189501 | G20: 72282.07 | H20: 4107.8 | V20: =SUM(I20:T20) -> 0 | W20: =V20+G20+H20 -> 76389.87
B21: thereof external | D21: 189501 | G21: 292187.94 | H21: 93447.47 | V21: =SUM(I21:T21) -> 0 | W21: =V21+G21+H21 -> 385635.41
B22: BURDEN COSTS MATERIAL 8,5% | C22: 0.1 | D22: 32215.17 | G22: 34950.373 | H22: 9755.527 | V22: =SUM(I22:T22) -> 0 | W22: =V22+G22+H22 -> 44705.9
B23: ="INTEREST ("&#REF!*100&"% rate, 8 years, calculatory)" -> #REF! | C23: 0.04 | D23: 828552.87 | G23: 808396.11 | H23: 41050.464 | V23: =SUM(I23:T23) -> 0 | W23: =V23+G23+H23 -> 849446.57
B24: SUBCONTRACTOR | D24: 3388674 | G24: 3498124.5 | H24: 839003.81 | V24: =SUM(I24:T24) -> 0 | W24: =V24+G24+H24 -> 4337128.3
B25: thereof internal | D25: 15000 | G25: 50672 | H25: 0 | V25: =SUM(I25:T25) -> 0 | W25: =V25+G25+H25 -> 50672
B26: thereof external | D26: 3373674 | G26: 3447452.5 | H26: 839003.81 | V26: =SUM(I26:T26) -> 0 | W26: =V26+G26+H26 -> 4286456.3
B27: HANDLING FEE SUBCON 15% | C27: 0.15 | D27: 508301.1 | G27: 524718.68 | H27: 125850.57 | V27: =SUM(I27:T27) -> 0 | W27: =V27+G27+H27 -> 650569.25
B28: LABOR COSTS | D28: 810549 | G28: 1655476.5 | H28: 336746.1 | V28: =SUM(I28:T28) -> 0 | W28: =V28+G28+H28 -> 1992222.6
B29: BURDEN COSTS LABOR 11,5% | C29: 0.14 | D29: 93213.135 | G29: 209573.3 | H29: 47144.454 | V29: =SUM(I29:T29) -> 0 | W29: =V29+G29+H29 -> 256717.75
B30: SUBTOTAL Cost of Products Sold | D30: 11023300 | G30: =SUM(G17:G19,G22:G24,G27:G29) -> 10603248 | H30: =SUM(H17:H19,H22:H24,H27:H29) -> 2075901.7 | V30: =SUM(V17:V19,V22:V24,V27:V29) -> 0 | W30: =SUM(W17:W19,W22:W24,W27:W29) -> 12679150
B31: DIVISION ALLOCATION RATE 15% | C31: 0.15 | D31: 944665.85 | G31: 969428.92 | H31: =SUM(H17,H19,H22,H28:H29)*$C$31 -> 160499.53 | V31: =SUM(I31:T31) -> 0 | W31: =V31+G31+H31 -> 1129928.4
H32: 0 | V32: =SUM(I32:T32) -> 0 | W32: =V32+G32+H32 -> 0
B33: OTHER DIRECT PROJECT COSTS: | H33: 0 | V33: =SUM(I33:T33) -> 0 | W33: =V33+G33+H33 -> 0
B34: TRAVEL | D34: 239094 | G34: 452673.42 | H34: 89508.43 | V34: =SUM(I34:T34) -> 0 | W34: =V34+G34+H34 -> 542181.85
B35: AGENTS/COMMISSION (calculatory) | D35: 1531302.3 | G35: 986353.85 | H35: 112800 | V35: =SUM(I35:T35) -> 0 | W35: =V35+G35+H35 -> 1099153.9
B36: OTHER | D36: 179047 | G36: 545122.89 | H36: 62568.5 | V36: =SUM(I36:T36) -> 0 | W36: =V36+G36+H36 -> 607691.39
B37: LDs | G37: 0 | V37: =SUM(I37:T37) -> 0 | W37: =V37+G37+H37 -> 0
B38: SALES TAX (payable) | H38: 0 | V38: =SUM(I38:T38) -> 0 | W38: =V38+G38 -> 0
B39: RISK BUDGET | G39: 0 | H39: 0 | V39: =SUM(I39:T39) -> 0 | W39: =V39+G39+H39 -> 0
V40: =SUM(I40:T40) -> 0 | W40: =V40+G40+H40 -> 0
B41: CONSOLIDATION DIFFERENCE | G41: 0 | H41: 0 | V41: =SUM(I41:T41) -> 0 | W41: =V41+G41+H41 -> 0
B42: ACCRUALS | G42: 0 | H42: 0 | V42: =SUM(I42:T42) -> 0 | W42: =V42+G42+H42 -> 0
B43: WIP | G43: 0 | H43: 0 | V43: =SUM(I43:T43) -> 0 | W43: =V43+G43+H43 -> 0
V44: =SUM(I44:T44) -> 0 | W44: =V44+G44+H44 -> 0
...

Sheet ROP-Michał-2024
A1: Nr aut. | B1: Lokalizacja automatu | D1: 45292 | Q1: 45292 | AT1: 45292 | BH1: 45323 | CK1: 45352 | CY1: 45352 | EB1: 45383 | EP1: 45383 | FS1: 45413 | GG1: 45413 | HJ1: 45444 | HX1: 45444 | JA1: 45474 | JO1: 45474 | KR1: 45505 | LF1: 45505 | MI1: 45536 | MW1: 45536 | NZ1: 45566 | ON1: 45566 | PQ1: 45597 | QE1: 45597 | RH1: 45627 | RV1: 45627 | SY1: TOTAL 2024
C2: Rodzaj automatu | D2: Brutto IC | E2: Brutto PR | F2: Brutto KW | G2: Brutto PP | H2: Brutto Arriva | I2: Brutto SKM | J2: Brutto KMŁ | K2: Brutto KD | L2: Brutto KŚ | M2: Brutto ŁKA | N2: W tym płatności kartowe | O2: W tym płatności gotówką | P2: Ilość biletów | Q2: Brutto Total | R2: Prowizja IC | S2: Prowizja PR | T2: Prowizja KW | U2: Prowizja PP | V2: Prowizja ARP | W2: Prowizja SKM | X2: Prowizja KMŁ | Y2: Prowizja KD | Z2: Prowizja KŚ | AA2: Prowizja ŁKA | AB2: Prowizja Suma | AC2: Czynsz | AD2: Prąd | AE2: Elavon | AF2: Poczta Polska | AG2: Amortyzacja | AH2: Utrzymanie oprogr. Centreo | AI2: Papier | AJ2: Transmisja danych | AK2: Serwis* | AL2: Polisa | AM2: Total TVMs Direct Costs | AN2: Non TVMs project fixed costs | AO2: Project Variable costs | AP2: OH | AQ2: Total Other Project Costs | AR2: Total cost of TVM | AS2: Proift/loss | AT2: Brutto IC | AU2: Brutto PR | AV2: Brutto KW | AW2: Brutto PP | AX2: Brutto Arriva | AY2: Brutto SKM | AZ2: Brutto KMŁ | BA2: Brutto KD | BB2: Brutto KŚ | BC2: Brutto ŁKA | BD2: W tym płatności kartowe | BE2: W tym płatności gotówką | BF2: Ilość biletów | BG2: Rodzaj automatu | BH2: Brutto Total | BI2: Prowizja IC | BJ2: Prowizja PR | BK2: Prowizja KW | BL2: Prowizja PP | BM2: Prowizja ARP | BN2: Prowizja SKM | BO2: Prowizja KMŁ | BP2: Prowizja KD | BQ2: Prowizja KŚ | BR2: Prowizja ŁKA | BS2: Prowizja Suma | BT2: Czynsz | BU2: Prąd | BV2: Elavon | BW2: Poczta Polska | BX2: Amortyzacja | BY2: Utrzymanie oprogr. Centreo | BZ2: Papier | CA2: Transmisja danych | CB2: Serwis* | CC2: Polisa | CD2: Total TVMs Direct Costs | CE2: Non TVMs project fixed costs | CF2: Project Variable costs | CG2: OH | CH2: Total Other Project Costs | CI2: Total cost of TVM | CJ2: Proift/loss | CK2: Brutto IC | CL2: Brutto PR | CM2: Brutto KW | CN2: Brutto PP | CO2: Brutto Arriva | CP2: Brutto SKM | CQ2: Brutto KMŁ | CR2: Brutto KD | CS2: Brutto KŚ | CT2: Brutto ŁKA | CU2: W tym płatności kartowe | CV2: W tym płatności gotówką | CW2: Ilość biletów | CX2: Rodzaj automatu | CY2: Brutto Total | CZ2: Prowizja IC | DA2: Prowizja PR | DB2: Prowizja KW | DC2: Prowizja PP | DD2: Prowizja ARP | DE2: Prowizja SKM | DF2: Prowizja KMŁ | DG2: Prowizja KD | DH2: Prowizja KŚ | DI2: Prowizja ŁKA | DJ2: Prowizja Suma | DK2: Czynsz | DL2: Prąd | DM2: Elavon | DN2: Poczta Polska | DO2: Amortyzacja | DP2: Utrzymanie oprogr. Centreo | DQ2: Papier | DR2: Transmisja danych | DS2: Serwis* | DT2: Polisa | DU2: Total TVMs Direct Costs | DV2: Non TVMs project fixed costs | DW2: Project Variable costs | DX2: OH | DY2: Total Other Project Costs | DZ2: Total cost of TVM | EA2: Proift/loss | EB2: Brutto IC | EC2: Brutto PR | ED2: Brutto KW | EE2: Brutto PP | EF2: Brutto Arriva | EG2: Brutto SKM | EH2: Brutto KMŁ | EI2: Brutto KD | EJ2: Brutto KŚ | EK2: Brutto ŁKA | EL2: W tym płatności kartowe | EM2: W tym płatności gotówką | EN2: Ilość biletów | EO2: Rodzaj automatu | EP2: Brutto Total | EQ2: Prowizja IC | ER2: Prowizja PR | ES2: Prowizja KW | ET2: Prowizja PP | EU2: Prowizja ARP | EV2: Prowizja SKM | EW2: Prowizja KMŁ | EX2: Prowizja KD | EY2: Prowizja KŚ | EZ2: Prowizja ŁKA | FA2: Prowizja Suma | FB2: Czynsz | FC2: Prąd | FD2: Elavon | FE2: Poczta Polska | FF2: Amortyzacja | FG2: Utrzymanie oprogr. Centreo | FH2: Papier | FI2: Transmisja danych | FJ2: Serwis* | FK2: Polisa | FL2: Total TVMs Direct Costs | FM2: Non TVMs project fixed costs | FN2: Project Variable costs | FO2: OH | FP2: Total Other Project Costs | FQ2: Total cost of TVM | FR2: Proift/loss | FS2: Brutto IC | FT2: Brutto PR | FU2: Brutto KW | FV2: Brutto PP | FW2: Brutto Arriva | FX2: Brutto SKM | FY2: Brutto KMŁ | FZ2: Brutto KD | GA2: Brutto KŚ | GB2: Brutto ŁKA | GC2: W tym płatności kartowe | GD2: W tym płatności gotówką | GE2: Ilość biletów | GF2: Rodzaj automatu | GG2: Brutto Total | GH2: Prowizja IC | GI2: Prowizja PR | GJ2: Prowizja KW | GK2: Prowizja PP | GL2: Prowizja ARP | GM2: Prowizja SKM | GN2: Prowizja KMŁ | GO2: Prowizja KD | GP2: Prowizja KŚ | GQ2: Prowizja ŁKA | GR2: Prowizja Suma | GS2: Czynsz | GT2: Prąd | GU2: Elavon | GV2: Poczta Polska | GW2: Amortyzacja | GX2: Utrzymanie oprogr. Centreo | GY2: Papier | GZ2: Transmisja danych | HA2: Serwis* | HB2: Polisa | HC2: Total TVMs Direct Costs | HD2: Non TVMs project fixed costs | HE2: Project Variable costs | HF2: OH | HG2: Total Other Project Costs | HH2: Total cost of TVM | HI2: Proift/loss | HJ2: Brutto IC | HK2: Brutto PR | HL2: Brutto KW | HM2: Brutto PP | HN2: Brutto Arriva | HO2: Brutto SKM | HP2: Brutto KMŁ | HQ2: Brutto KD | HR2: Brutto KŚ | HS2: Brutto ŁKA | HT2: W tym płatności kartowe | HU2: W tym płatności gotówką | HV2: Ilość biletów | HW2: Rodzaj automatu | HX2: Brutto Total | HY2: Prowizja IC | HZ2: Prowizja PR | IA2: Prowizja KW | IB2: Prowizja PP | IC2: Prowizja ARP | ID2: Prowizja SKM | IE2: Prowizja KMŁ | IF2: Prowizja KD | IG2: Prowizja KŚ | IH2: Prowizja ŁKA | II2: Prowizja Suma | IJ2: Czynsz | IK2: Prąd | IL2: Elavon | IM2: Poczta Polska | IN2: Amortyzacja | IO2: Utrzymanie oprogr. Centreo | IP2: Papier | IQ2: Transmisja danych | IR2: Serwis* | IS2: Polisa | IT2: Total TVMs Direct Costs | IU2: Non TVMs project fixed costs | IV2: Project Variable costs | IW2: OH | IX2: Total Other Project Costs | IY2: Total cost of TVM | IZ2: Proift/loss | JA2: Brutto IC | JB2: Brutto PR | JC2: Brutto KW | JD2: Brutto PP | JE2: Brutto Arriva | JF2: Brutto SKM | JG2: Brutto KMŁ | JH2: Brutto KD | JI2: Brutto KŚ | JJ2: Brutto ŁKA | JK2: W tym płatności kartowe | JL2: W tym płatności gotówką | JM2: Ilość biletów | JN2: Rodzaj automatu | JO2: Brutto Total | JP2: Prowizja IC | JQ2: Prowizja PR | JR2: Prowizja KW | JS2: Prowizja PP | JT2: Prowizja ARP | JU2: Prowizja SKM | JV2: Prowizja KMŁ | JW2: Prowizja KD | JX2: Prowizja KŚ | JY2: Prowizja ŁKA | JZ2: Prowizja Suma | KA2: Czynsz | KB2: Prąd | KC2: Elavon | KD2: Poczta Polska | KE2: Amortyzacja | KF2: Utrzymanie oprogr. Centreo | KG2: Papier | KH2: Transmisja danych | KI2: Serwis* | KJ2: Polisa | KK2: Total TVMs Direct Costs | KL2: Non TVMs project fixed costs | KM2: Project Variable costs | KN2: OH | KO2: Total Other Project Costs | KP2: Total cost of TVM | KQ2: Proift/loss | KR2: Brutto IC | KS2: Brutto PR | KT2: Brutto KW | KU2: Brutto PP | KV2: Brutto Arriva | KW2: Brutto SKM | KX2: Brutto KMŁ | KY2: Brutto KD | KZ2: Brutto KŚ | LA2: Brutto ŁKA | LB2: W tym płatności kartowe | LC2: W tym płatności gotówką | LD2: Ilość biletów | LE2: Rodzaj automatu | LF2: Brutto Total | LG2: Prowizja IC | LH2: Prowizja PR | LI2: Prowizja KW | LJ2: Prowizja PP | LK2: Prowizja ARP | LL2: Prowizja SKM | LM2: Prowizja KMŁ | LN2: Prowizja KD | LO2: Prowizja KŚ | LP2: Prowizja ŁKA | LQ2: Prowizja Suma | LR2: Czynsz | LS2: Prąd | LT2: Elavon | LU2: Poczta Polska | LV2: Amortyzacja | LW2: Utrzymanie oprogr. Centreo | LX2: Papier | LY2: Transmisja danych | LZ2: Serwis* | MA2: Polisa | MB2: Total TVMs Direct Costs | MC2: Non TVMs project fixed costs | MD2: Project Variable costs | ME2: OH | MF2: Total Other Project Costs | MG2: Total cost of TVM | MH2: Proift/loss | MI2: Brutto IC | MJ2: Brutto PR | MK2: Brutto KW | ML2: Brutto PP | MM2: Brutto Arriva | MN2: Brutto SKM | MO2: Brutto KMŁ | MP2: Brutto KD | MQ2: Brutto KŚ | MR2: Brutto ŁKA | MS2: W tym płatności kartowe | MT2: W tym płatności gotówką | MU2: Ilość biletów | MV2: Rodzaj automatu | MW2: Brutto Total | MX2: Prowizja IC | MY2: Prowizja PR | MZ2: Prowizja KW | NA2: Prowizja PP | NB2: Prowizja ARP | NC2: Prowizja SKM | ND2: Prowizja KMŁ | NE2: Prowizja KD | NF2: Prowizja KŚ | NG2: Prowizja ŁKA | NH2: Prowizja Suma | NI2: Czynsz | NJ2: Prąd | NK2: Elavon | NL2: Poczta Polska | NM2: Amortyzacja | NN2: Utrzymanie oprogr. Centreo | NO2: Papier | NP2: Transmisja danych | NQ2: Serwis* | NR2: Polisa | NS2: Total TVMs Direct Costs | NT2: Non TVMs project fixed costs | NU2: Project Variable costs | NV2: OH | NW2: Total Other Project Costs | NX2: Total cost of TVM | NY2: Proift/loss | NZ2: Brutto IC | OA2: Brutto PR | OB2: Brutto KW | OC2: Brutto PP | OD2: Brutto Arriva | OE2: Brutto SKM | OF2: Brutto KMŁ | OG2: Brutto KD | OH2: Brutto KŚ | OI2: Brutto ŁKA | OJ2: W tym płatności kartowe | OK2: W tym płatności gotówką | OL2: Ilość biletów | OM2: Rodzaj automatu | ON2: Brutto Total | OO2: Prowizja IC | OP2: Prowizja PR | OQ2: Prowizja KW | OR2: Prowizja PP | OS2: Prowizja ARP | OT2: Prowizja SKM | OU2: Prowizja KMŁ | OV2: Prowizja KD | OW2: Prowizja KŚ | OX2: Prowizja ŁKA | OY2: Prowizja Suma | OZ2: Czynsz | PA2: Prąd | PB2: Elavon | PC2: Poczta Polska | PD2: Amortyzacja | PE2: Utrzymanie oprogr. Centreo | PF2: Papier | PG2: Transmisja danych | PH2: Serwis* | PI2: Polisa | PJ2: Total TVMs Direct Costs | PK2: Non TVMs project fixed costs | PL2: Project Variable costs | PM2: OH | PN2: Total Other Project Costs | PO2: Total cost of TVM | PP2: Proift/loss | PQ2: Brutto IC | PR2: Brutto PR | PS2: Brutto KW | PT2: Brutto PP | PU2: Brutto Arriva | PV2: Brutto SKM | PW2: Brutto KMŁ | PX2: Brutto KD | PY2: Brutto KŚ | PZ2: Brutto ŁKA | QA2: W tym płatności kartowe | QB2: W tym płatności gotówką | QC2: Ilość biletów | QD2: Rodzaj automatu | QE2: Brutto Total | QF2: Prowizja IC | QG2: Prowizja PR | QH2: Prowizja KW | QI2: Prowizja PP | QJ2: Prowizja ARP | QK2: Prowizja SKM | QL2: Prowizja KMŁ | QM2: Prowizja KD | QN2: Prowizja KŚ | QO2: Prowizja ŁKA | QP2: Prowizja Suma | QQ2: Czynsz | QR2: Prąd | QS2: Elavon | QT2: Poczta Polska | QU2: Amortyzacja | QV2: Utrzymanie oprogr. Centreo | QW2: Papier | QX2: Transmisja danych | QY2: Serwis* | QZ2: Polisa | RA2: Total TVMs Direct Costs | RB2: Non TVMs project fixed costs | RC2: Project Variable costs | RD2: OH | RE2: Total Other Project Costs | RF2: Total cost of TVM | RG2: Proift/loss | RH2: Brutto IC | RI2: Brutto PR | RJ2: Brutto KW | RK2: Brutto PP | RL2: Brutto Arriva | RM2: Brutto SKM | RN2: Brutto KMŁ | RO2: Brutto KD | RP2: Brutto KŚ | RQ2: Brutto ŁKA | RR2: W tym płatności kartowe | RS2: W tym płatności gotówką | RT2: Ilość biletów | RU2: Rodzaj automatu | RV2: Brutto Total | RW2: Prowizja IC | RX2: Prowizja PR | RY2: Prowizja KW | RZ2: Prowizja PP | SA2: Prowizja ARP | SB2: Prowizja SKM | SC2: Prowizja KMŁ | SD2: Prowizja KD | SE2: Prowizja KŚ | SF2: Prowizja ŁKA | SG2: Prowizja Suma | SH2: Czynsz | SI2: Prąd | SJ2: Elavon | SK2: Poczta Polska | SL2: Amortyzacja | SM2: Utrzymanie oprogr. Centreo | SN2: Papier | SO2: Transmisja danych | SP2: Serwis* | SQ2: Polisa | SR2: Total TVMs Direct Costs | SS2: Non TVMs project fixed costs | ST2: Project Variable costs | SU2: OH | SV2: Total Other Project Costs | SW2: Total cost of TVM | SX2: Proift/loss | SY2: Brutto Total | SZ2: Prowizja Suma | TA2: Total cost of TVM | TB2: Prowizja Suma | TC2: Uwagi MW | TD2: UWAGI AS | TE2: Rekomendacja
A3: 1101 | B3: 1101_KRA_GL | C3: MOVE S320 | D3: 19509.23 | E3: 12587.13 | F3: 196.25 | G3: 0 | H3: 0 | I3: 0 | J3: 0 | K3: 40 | L3: 2122.08 | M3: 0 | N3: 34454.69 | O3: 0 | P3: 1379 | Q3: =SUM(D3:M3) -> 34454.69 | R3: 1623.98 | S3: 4357.14 | T3: 12.54 | U3: 0 | V3: 0 | W3: 0 | X3: 750 | Y3: 2.78 | Z3: 117.89 | AA3: 0 | AB3: =SUM(R3:AA3) -> 6864.33 | AD3: 276.52 | AE3: =(N3/$N$116)*21028.32 -> 374.61888 | AF3: =(O3/$O$116)*15324.97 -> 0 | AH3: 20 | AJ3: 5 | AK3: =39081.75/95 -> 411.38684 | AM3: =SUM(AC3:AL3) -> 1087.5257 | AN3: =61284.58/95 -> 645.10084 | AO3: 0 | AP3: =(AN3+AO3)*30% -> 193.53025 | AQ3: =SUM(AN3:AP3) -> 838.63109 | AR3: =AM3+AQ3 -> 1926.1568 | AS3: =AB3-AR3 -> 4938.1732 | AT3: 16000.97 | AU3: 12307.76 | AV3: 0 | AW3: 0 | AX3: 0 | AY3: 0 | AZ3: 0 | BA3: 43.8 | BB3: 1755 | BC3: 0 | BD3: 30107.53 | BE3: 0 | BF3: 1292 | BG3: MOVE S320 | BH3: =SUM(AT3:BC3) -> 30107.53 | BI3: 1331.93 | BJ3: 4357.14 | BK3: 0 | BL3: 0 | BM3: 0 | BN3: 0 | BO3: 750 | BP3: 3.04 | BQ3: 97.5 | BR3: 0 | BS3: =SUM(BI3:BR3) -> 6539.61 | BU3: 276.52 | BV3: =(BD3/$BD$116)*21083.85 -> 330.21082 | BW3: =(BE3/$O$116)*12925.76 -> 0 | BY3: 20 | CA3: 5 | CB3: =37537.5/96 -> 391.01562 | CD3: =SUM(BT3:CC3) -> 1022.7464 | CE3: =63860.36/96 -> 665.21208 | CG3: =(CE3+CF3)*30% -> 199.56363 | CH3: =SUM(CE3:CG3) -> 864.77571 | CI3: =CD3+CH3 -> 1887.5221 | CJ3: =BS3-CI3 -> 4652.0879 | CK3: 22187.93 | CL3: 9297.55 | CM3: 0 | CN3: 0 | CO3: 0 | CP3: 0 | CQ3: 13043.52 | CR3: 23.6 | CS3: 1586.68 | CT3: 0 | CU3: 46139.28 | CV3: 0 | CW3: 1895 | CX3: MOVE S320 | CY3: =SUM(CK3:CT3) -> 46139.28 | CZ3: 1846.95 | DA3: 4357.14 | DB3: 0 | DC3: 0 | DD3: 0 | DE3: 0 | DF3: 750 | DG3: 1.64 | DH3: 88.11 | DI3: 0 | DJ3: =SUM(CZ3:DI3) -> 7043.84 | DM3: =(CU3/$CU$116)*24055.75 -> 501.59846 | DN3: =(CV3/$O$116)*16258.02 -> 0 | DP3: 20 | DR3: 5 | DS3: =42418.5/99 -> 428.4697 | DU3: =SUM(DK3:DT3) -> 955.06815 | DV3: =59038.72/99 -> 596.35071 | DX3: =(DV3+DW3)*30% -> 178.90521 | DY3: =SUM(DV3:DX3) -> 775.25592 | DZ3: =DU3+DY3 -> 1730.3241 | EA3: =DJ3-DZ3 -> 5313.5159 | EB3: 14559.71 | EC3: 10885.16 | ED3: 0 | EE3: 0 | EF3: 0 | EG3: 0 | EH3: 14262.2 | EI3: 0 | EJ3: 2111.15 | EK3: 0 | EL3: 41818.22 | EM3: 0 | EN3: 2010 | EO3: MOVE S320 | EP3: =SUM(EB3:EK3) -> 41818.22 | EQ3: 1211.97 | ER3: 4357.14 | ES3: 0 | ET3: 0 | EU3: 0 | EV3: 0 | EW3: 750 | EX3: 0 | EY3: 117.29 | EZ3: 0 | FA3: =SUM(EQ3:EZ3) -> 6436.4 | FB3: 1134.23 | FC3: 276.52 | FD3: =(EL3/$EL$116)*26325.65 -> 466.7771 | FE3: =(EM3/$O$116)*14846.27 -> 0 | FF3: =52000/60 -> 866.66667 | FG3: 20 | FH3: =14375.2/102 -> 140.93333 | FI3: 5 | FJ3: =43317.38/102 -> 424.6802 | FL3: =SUM(FB3:FK3) -> 3334.8073 | FM3: =67770.74/102 -> 664.41902 | FO3: =(FM3+FN3)*30% -> 199.32571 | FP3: =SUM(FM3:FO3) -> 863.74473 | FQ3: =FL3+FP3 -> 4198.552 | FR3: =FA3-FQ3 -> 2237.848 | FS3: 21194.7 | FT3: 15063.19 | FU3: 0 | FV3: 0 | FW3: 0 | FX3: 0 | FY3: 18929.76 | FZ3: 0 | GA3: 3567.38 | GB3: 0 | GC3: 58755.03 | GD3: 0 | GE3: 2715 | GF3: MOVE S320 | GG3: =SUM(FS3:GB3) -> 58755.03 | GH3: 1764.28 | GI3: 4357.14 | GJ3: 0 | GK3: 0 | GL3: 0 | GM3: 0 | GN3: 750 | GO3: 0 | GP3: 198.13 | GQ3: 0 | GR3: =SUM(GH3:GQ3) -> 7069.55 | GS3: 1134.23 | GT3: 276.52 | GU3: =(GC3/$GC$116)*30198.86 -> 651.07886 | GV3: =(GD3/$O$116)*16844.27 -> 0 | GW3: =52000/60 -> 866.66667 | GX3: 20 | GY3: =18860.4/102 -> 184.90588 | GZ3: 5 | HA3: =36564.75/102 -> 358.47794 | HC3: =SUM(GS3:HB3) -> 3496.8793 | HD3: =88425.86/102 -> 866.9202 | HF3: =(HD3+HE3)*30% -> 260.07606 | HG3: =SUM(HD3:HF3) -> 1126.9963 | HH3: =HC3+HG3 -> 4623.8756 | HI3: =GR3-HH3 -> 2445.6744 | HJ3: 24995.47 | HK3: 15777.34 | HL3: 7.8 | HM3: 0 | HN3: 0 | HO3: 0 | HP3: 19587.2 | HQ3: 11.56 | HR3: 2396.51 | HS3: 0 | HT3: 62775.88 | HU3: 0 | HV3: 2924 | HW3: MOVE S320 | HX3: =SUM(HJ3:HS3) -> 62775.88 | HY3: 2080.65 | HZ3: 4357.14 | IA3: 0.5 | IB3: 0 | IC3: 0 | ID3: 0 | IE3: 750 | IF3: 0.8 | IG3: 133.02 | IH3: 0 | II3: =SUM(HY3:IH3) -> 7322.11 | IJ3: 1134.23 | IK3: 276.52 | IL3: =(HT3/$HT$116)*31846.83 -> 695.3971 | IM3: =(HU3/$O$116)*17321.85 -> 0 | IN3: =52000/60 -> 866.66667 | IO3: 20 | IP3: =24366/105 -> 232.05714 | IQ3: 5 | IR3: =46791/105 -> 445.62857 | IT3: =SUM(IJ3:IS3) -> 3675.4995 | IU3: =56573.45/105 -> 538.79476 | IW3: =(IU3+IV3)*30% -> 161.63843 | IX3: =SUM(IU3:IW3) -> 700.43319 | IY3: =IT3+IX3 -> 4375.9327 | IZ3: =II3-IY3 -> 2946.1773 | JA3: 23605.13 | JB3: 13430.65 | JC3: 23.2 | JD3: 0 | JE3: 0 | JF3: 0 | JG3: 21822.71 | JH3: 0 | JI3: 3176.16 | JJ3: 0 | JK3: 62057.85 | JL3: 0 | JM3: 2810 | JN3: MOVE S320 | JO3: =SUM(JA3:JJ3) -> 62057.85 | JP3: 1964.91 | JQ3: 4357.14 | JR3: 1.48 | JS3: 0 | JT3: 0 | JU3: 0 | JV3: 750 | JW3: 0 | JX3: 176.28 | JY3: 0 | JZ3: =SUM(JP3:JY3) -> 7249.81 | KA3: 1134.23 | KB3: 276.52 | KC3: =(JK3/$N$116)*39010.72 -> 1251.7495 | KD3: =(JL3/$O$116)*19244.4 -> 0 | KE3: =52000/60 -> 866.66667 | KF3: 20 | KH3: 5 | KI3: =58143.75/107 -> 543.39953 | KK3: =SUM(KA3:KJ3) -> 4097.5657 | KL3: =53213.34/107 -> 497.32093 | KN3: =(KL3+KM3)*30% -> 149.19628 | KO3: =SUM(KL3:KN3) -> 646.51721 | KP3: =KK3+KO3 -> 4744.0829 | KQ3: =JZ3-KP3 -> 2505.7271 | KR3: 29275.9 | KS3: 16605.75 | KT3: 0 | KU3: 0 | KV3: 0 | KW3: 0 | KX3: 23503.26 | KY3: 123.7 | KZ3: 3051.23 | LA3: 0 | LB3: 72559.84 | LC3: 0 | LD3: 2982 | LE3: MOVE S320 | LF3: =SUM(KR3:LA3) -> 72559.84 | LG3: 2436.94 | LH3: 4357.14 | LI3: 0 | LJ3: 0 | LK3: 0 | LL3: 0 | LM3: 750 | LN3: 8.59 | LO3: 169.35 | LP3: 0 | LQ3: =SUM(LG3:LP3) -> 7722.02 | LR3: 1134.23 | LS3: 264 | LT3: =(LB3/$LB$116)*39133.48 -> 739.75685 | LU3: =(LC3/$O$116)*17015.75 -> 0 | LV3: =52000/60 -> 866.66667 | LW3: 20 | LY3: 5 | LZ3: =54360/107 -> 508.03738 | MB3: =SUM(LR3:MA3) -> 3537.6909 | MC3: =63509.75/107 -> 593.54907 | ME3: =(MC3+MD3)*30% -> 178.06472 | MF3: =SUM(MC3:ME3) -> 771.61379 | MG3: =MB3+MF3 -> 4309.3047 | MH3: =LQ3-MG3 -> 3412.7153 | MI3: 23943.49 | MJ3: 12050.12 | MK3: 0 | ML3: 0 | MM3: 0 | MN3: 0 | MO3: 21215.44 | MP3: 0 | MQ3: 1955.61 | MR3: 0 | MS3: 59164.66 | MT3: 0 | MU3: 2608 | MV3: MOVE S320 | MW3: =SUM(MI3:MR3) -> 59164.66 | MX3: 1993.08 | MY3: 4357.14 | MZ3: 0 | NA3: 0 | NB3: 0 | NC3: 0 | ND3: 750 | NE3: 0 | NF3: 108.64 | NG3: 0 | NH3: =SUM(MX3:NG3) -> 7208.86 | NI3: 1134.23 | NJ3: 264 | NK3: =(MS3/$N$116)*0 -> 0 | NL3: =(MT3/$O$116)*13804.26 -> 0 | NM3: =52000/60 -> 866.66667 | NN3: 20 | NP3: 5 | NQ3: =51195/109 -> 469.6789 | NS3: =SUM(NI3:NR3) -> 2759.5756 | NT3: =78812.25/109 -> 723.04817 | NV3: =(NT3+NU3)*30% -> 216.91445 | NW3: =SUM(NT3:NV3) -> 939.96261 | NX3: =NS3+NW3 -> 3699.5382 | NY3: =NH3-NX3 -> 3509.3218 | NZ3: 21543.12 | OA3: 11947.08 | OB3: 0 | OC3: 0 | OD3: 0 | OE3: 0 | OF3: 21862.42 | OG3: 11.12 | OH3: 2000.44 | OI3: 0 | OJ3: 57364.18 | OK3: =ON3-OJ3 -> 0 | OL3: 2783 | OM3: MOVE S320 | ON3: =SUM(NZ3:OI3) -> 57364.18 | OO3: 1793.27 | OP3: 4357.14 | OQ3: 0 | OR3: 0 | OS3: 0 | OT3: 0 | OU3: 750 | OV3: 0.77 | OW3: 111.14 | OX3: 0 | OY3: =SUM(OO3:OX3) -> 7012.32 | OZ3: 1134.23 | PA3: 264 | PB3: =(OJ3/$OJ$116)*56307.47 -> 1240.4006 | PC3: =(OK3/$O$116)*16757.91 -> 0 | PD3: =52000/60 -> 866.66667 | PE3: 20 | PF3: =3288/100 -> 32.88 | PG3: 5 | PH3: =54472.54/110 -> 495.20491 | PJ3: =SUM(OZ3:PI3) -> 4058.3822 | PK3: =70758.13/110 -> 643.25573 | PM3: =(PK3+PL3)*30% -> 192.97672 | PN3: =SUM(PK3:PM3) -> 836.23245 | PO3: =PJ3+PN3 -> 4894.6146 | PP3: =OY3-PO3 -> 2117.7054 | PQ3: 17457.73 | PR3: 11118.41 | PS3: 0 | PT3: 0 | PU3: 0 | PV3: 0 | PW3: 17458.67 | PX3: 0 | PY3: 1963.77 | PZ3: 11.2 | QA3: 48009.78 | QB3: 0 | QC3: 2415 | QD3: MOVE S320 | QE3: =SUM(PQ3:PZ3) -> 48009.78 | QF3: 1453.2 | QG3: 4357.14 | QH3: 0 | QI3: 0 | QJ3: 0 | QK3: 0 | QL3: 750 | QM3: 0 | QN3: 109.1 | QO3: 0.62 | QP3: =SUM(QF3:QO3) -> 6670.06 | QQ3: 1134.23 | QR3: 264 | QS3: =(QA3/$QA$116)*27743.06 -> 564.35525 | QT3: =(QB3/$O$116)*10429.01 -> 0 | QU3: =52000/60 -> 866.66667 | QV3: 20 | QW3: =2074.8/110 -> 18.861818 | QX3: 5 | QY3: =47096.25/110 -> 428.14773 | RA3: =SUM(QQ3:QZ3) -> 3301.2615 | RB3: =68119.05/110 -> 619.26409 | RD3: =(RB3+RC3)*30% -> 185.77923 | RE3: =SUM(RB3:RD3) -> 805.04332 | RF3: =RA3+RE3 -> 4106.3048 | RG3: =QP3-RF3 -> 2563.7552 | RH3: 22439.51 | RI3: 13094.7 | RJ3: 0 | RK3: 0 | RL3: 0 | RM3: 0 | RN3: 18726.04 | RO3: 0 | RP3: 1695.5 | RQ3: 0 | RR3: 55955.75 | RS3: 0 | RT3: 2503 | RU3: MOVE S320 | RV3: =SUM(RH3:RQ3) -> 55955.75 | RW3: 1867.88 | RX3: 4357.14 | RY3: 0 | RZ3: 0 | SA3: 0 | SB3: 0 | SC3: 750 | SD3: 0 | SE3: 94.2 | SF3: 0 | SG3: 6319.22 | SH3: 1134.23 | SI3: 264 | SJ3: =(RR3/$RR$116)*25115.94 -> 549.8719 | SK3: =(RS3/$O$116)*12319.54 -> 0 | SL3: =52000/60 -> 866.66667 | SM3: 20 | SN3: =56040/113 -> 495.9292 | SO3: 5 | SP3: =48423.75/113 -> 428.52876 | SR3: =SUM(SH3:SQ3) -> 3764.2265 | SS3: =67380.17/113 -> 596.28469 | SU3: =(SS3+ST3)*30% -> 178.88541 | SV3: =SUM(SS3:SU3) -> 775.1701 | SW3: =SR3+SV3 -> 4539.3966 | SX3: =SG3-SW3 -> 1779.8234 | SY3: =Q3+BH3+CY3+EP3+GG3+HX3+JO3+LF3+MW3+ON3+QE3+RV3 -> 629162.69 | SZ3: =AB3+BS3+DJ3+FA3+GR3+II3+JZ3+LQ3+NH3+OY3+QP3+SG3 -> 83458.13 | TA3: =AR3+CI3+DZ3+FQ3+HH3+IY3+KP3+MG3+NX3+PO3+RF3+SW3 -> 45035.605 | TB3: =SZ3-TA3 -> 38422.525 | TF3: Legenda: 1. Do 5 000 PLN 2. 5 001 - 10 000 3. > 10 001 - do relokacji
A4: 1102 | B4: 1102_ZIELON | C4: MOVE S320 | D4: 3004.91 | E4: 7573.64 | F4: 0 | G4: 0 | H4: 0 | I4: 0 | J4: 0 | K4: 104.08 | L4: 0 | M4: 0 | N4: 10682.63 | O4: =Q4-N4 -> 0 | P4: 946 | Q4: =SUM(D4:M4) -> 10682.63 | R4: 250.14 | S4: 4357.14 | T4: 0 | U4: 0 | V4: 0 | W4: 0 | X4: 0 | Y4: 7.23 | Z4: 0 | AA4: 0 | AB4: =SUM(R4:AA4) -> 4614.51 | AE4: =(N4/$N$116)*21028.32 -> 116.15008 | AF4: =(O4/$O$116)*15324.97 -> 0 | AH4: 20 | AJ4: 5 | AK4: =39081.75/95 -> 411.38684 | AM4: =SUM(AC4:AL4) -> 552.53692 | AN4: =61284.58/95 -> 645.10084 | AO4: 0 | AP4: =(AN4+AO4)*30% -> 193.53025 | AQ4: =SUM(AN4:AP4) -> 838.63109 | AR4: =AM4+AQ4 -> 1391.168 | AS4: =AB4-AR4 -> 3223.342 | AT4: 3605.52 | AU4: 8367.5 | AV4: 46.8 | AW4: 0 | AX4: 0 | AY4: 0 | AZ4: 0 | BA4: 73.26 | BB4: 0 | BC4: 0 | BD4: 12093.08 | BE4: =BH4-BD4 -> 0 | BF4: 942 | BG4: MOVE S320 | BH4: =SUM(AT4:BC4) -> 12093.08 | BI4: 300.12 | BJ4: 4357.14 | BK4: 2.99 | BL4: 0 | BM4: 0 | BN4: 0 | BO4: 0 | BP4: 5.09 | BQ4: 0 | BR4: 0 | BS4: =SUM(BI4:BR4) -> 4665.34 | BV4: =(BD4/$BD$116)*21083.85 -> 132.63346 | BW4: =(BE4/$O$116)*12925.76 -> 0 | BY4: 20 | CA4: 5 | CB4: =37537.5/96 -> 391.01562 | CD4: =SUM(BT4:CC4) -> 548.64908 | CE4: =63860.36/96 -> 665.21208 | CG4: =(CE4+CF4)*30% -> 199.56363 | CH4: =SUM(CE4:CG4) -> 864.77571 | CI4: =CD4+CH4 -> 1413.4248 | CJ4: =BS4-CI4 -> 3251.9152 | CK4: 2945.03 | CL4: 9835.59 | CM4: 65.6 | CN4: 0 | CO4: 0 | CP4: 0 | CQ4: 0 | CR4: 1203.42 | CS4: 0 | CT4: 0 | CU4: 14049.64 | CV4: =CY4-CU4 -> 0 | CW4: 1096 | CX4: MOVE S320 | CY4: =SUM(CK4:CT4) -> 14049.64 | CZ4: 245.14 | DA4: 4357.14 | DB4: 4.19 | DC4: 0 | DD4: 0 | DE4: 0 | DF4: 0 | DG4: 83.57 | DH4: 0 | DI4: 0 | DJ4: =SUM(CZ4:DI4) -> 4690.04 | DM4: =(CU4/$CU$116)*24055.75 -> 152.73922 | DN4: =(CV4/$O$116)*16258.02 -> 0 | DP4: 20 | DR4: 5 | DS4: =DS$3 -> 428.4697 | DU4: =SUM(DK4:DT4) -> 606.20892 | DV4: =DV$3 -> 596.35071 | DX4: =(DV4+DW4)*30% -> 178.90521 | DY4: =SUM(DV4:DX4) -> 775.25592 | DZ4: =DU4+DY4 -> 1381.4648 | EA4: =DJ4-DZ4 -> 3308.5752 | EB4: 2810.03 | EC4: 9531 | ED4: 50.53 | EE4: 0 | EF4: 0 | EG4: 0 | EH4: 0 | EI4: 1827.56 | EJ4: 0 | EK4: 0 | EL4: 14219.12 | EM4: =EP4-EL4 -> 0 | EN4: 1080 | EO4: MOVE S320 | EP4: =SUM(EB4:EK4) -> 14219.12 | EQ4: 233.91 | ER4: 4357.14 | ES4: 3.23 | ET4: 0 | EU4: 0 | EV4: 0 | EW4: 0 | EX4: 126.84 | EY4: 0 | EZ4: 0 | FA4: =SUM(EQ4:EZ4) -> 4721.12 | FD4: =(EL4/$EL$116)*26325.65 -> 158.71454 | FE4: =(EM4/$O$116)*14846.27 -> 0 | FF4: =52000/60 -> 866.66667 | FG4: 20 | FH4: =14375.2/102 -> 140.93333 | FI4: 5 | FJ4: =FJ$3 -> 424.6802 | FL4: =SUM(FB4:FK4) -> 1615.9947 | FM4: =FM$3 -> 664.41902 | FO4: =(FM4+FN4)*30% -> 199.32571 | FP4: =SUM(FM4:FO4) -> 863.74473 | FQ4: =FL4+FP4 -> 2479.7395 | FR4: =FA4-FQ4 -> 2241.3805 | FS4: 2996.19 | FT4: 12995.38 | FU4: 0.3 | FV4: 0 | FW4: 0 | FX4: 0 | FY4: 0 | FZ4: 2550.82 | GA4: 0 | GB4: 0 | GC4: 18542.69 | GD4: =GG4-GC4 -> 0 | GE4: 1382 | GF4: MOVE S320 | GG4: =SUM(FS4:GB4) -> 18542.69 | GH4: 249.4 | GI4: 4357.14 | GJ4: 0.02 | GK4: 0 | GL4: 0 | GM4: 0 | GN4: 0 | GO4: 176.71 | GP4: 0 | GQ4: 0 | GR4: =SUM(GH4:GQ4) -> 4783.27 | GU4: =(GC4/$GC$116)*30198.86 -> 205.47608 | GV4: =(GD4/$O$116)*16844.27 -> 0 | GW4: =52000/60 -> 866.66667 | GX4: 20 | GY4: =18860.4/102 -> 184.90588 | GZ4: 5 | HA4: =HA$3 -> 358.47794 | HC4: =SUM(GS4:HB4) -> 1640.5266 | HD4: =HD$3 -> 866.9202 | HF4: =(HD4+HE4)*30% -> 260.07606 | HG4: =SUM(HD4:HF4) -> 1126.9963 | HH4: =HC4+HG4 -> 2767.5228 | HI4: =GR4-HH4 -> 2015.7472 | HJ4: 5532.5 | HK4: 14804.05 | HL4: 0 | HM4: 0 | HN4: 0 | HO4: 0 | HP4: 0 | HQ4: 3062.04 | HR4: 0 | HS4: 0 | HT4: 23398.59 | HU4: =HX4-HT4 -> 0 | HV4: 1486 | HW4: MOVE S320 | HX4: =SUM(HJ4:HS4) -> 23398.59 | HY4: 460.53 | HZ4: 4357.14 | IA4: 0 | IB4: 0 | IC4: 0 | ID4: 0 | IE4: 0 | IF4: 212.64 | IG4: 0 | IH4: 0 | II4: =SUM(HY4:IH4) -> 5030.31 | IL4: =(HT4/$HT$116)*31846.83 -> 259.19687 | IM4: =(HU4/$O$116)*17321.85 -> 0 | IN4: =52000/60 -> 866.66667 | IO4: 20 | IP4: =24366/105 -> 232.05714 | IQ4: 5 | IR4: =IR$3 -> 445.62857 | IT4: =SUM(IJ4:IS4) -> 1828.5493 | IU4: =IU$3 -> 538.79476 | IW4: =(IU4+IV4)*30% -> 161.63843 | IX4: =SUM(IU4:IW4) -> 700.43319 | IY4: =IT4+IX4 -> 2528.9824 | IZ4: =II4-IY4 -> 2501.3276 | JA4: 6865.6 | JB4: 16029.97 | JC4: 71.76 | JD4: 0 | JE4: 0 | JF4: 0 | JG4: 0 | JH4: 3608.09 | JI4: 0 | JJ4: 0 | JK4: 26575.42 | JL4: =JO4-JK4 -> 0 | JM4: 1463 | JN4: MOVE S320 | JO4: =SUM(JA4:JJ4) -> 26575.42 | JP4: 571.5 | JQ4: 4357.14 | JR4: 4.58 | JS4: 0 | JT4: 0 | JU4: 0 | JV4: 0 | JW4: 250.34 | JX4: 0 | JY4: 0 | JZ4: =SUM(JP4:JY4) -> 5183.56 | KC4: =(JK4/$N$116)*39010.72 -> 536.0445 | KD4: =(JL4/$O$116)*19244.4 -> 0 | KE4: =52000/60 -> 866.66667 | KF4: 20 | KH4: 5 | KI4: =KI$3 -> 543.39953 | KK4: =SUM(KA4:KJ4) -> 1971.1107 | KL4: =KL$3 -> 497.32093 | KN4: =(KL4+KM4)*30% -> 149.19628 | KO4: =SUM(KL4:KN4) -> 646.51721 | KP4: =KK4+KO4 -> 2617.6279 | KQ4: =JZ4-KP4 -> 2565.9321 | KR4: 3897.22 | KS4: 12726.13 | KT4: 0.33 | KU4: 0 | KV4: 0 | KW4: 0 | KX4: 0 | KY4: 2710.18 | KZ4: 0 | LA4: 0 | LB4: 19333.86 | LC4: =LF4-LB4 -> 0 | LD4: 1129 | LE4: MOVE S320 | LF4: =SUM(KR4:LA4) -> 19333.86 | LG4: 324.41 | LH4: 4357.14 | LI4: 0.02 | LJ4: 0 | LK4: 0 | LL4: 0 | LM4: 0 | LN4: 188.2 | LO4: 0 | LP4: 0 | LQ4: =SUM(LG4:LP4) -> 4869.77 | LT4: =(LB4/$LB$116)*39133.48 -> 197.11118 | LU4: =(LC4/$O$116)*17015.75 -> 0 | LV4: =52000/60 -> 866.66667 | LW4: 20 | LY4: 5 | LZ4: =LZ$3 -> 508.03738 | MB4: =SUM(LR4:MA4) -> 1596.8152 | MC4: =MC$3 -> 593.54907 | ME4: =(MC4+MD4)*30% -> 178.06472 | MF4: =SUM(MC4:ME4) -> 771.61379 | MG4: =MB4+MF4 -> 2368.429 | MH4: =LQ4-MG4 -> 2501.341 | MI4: 3140.04 | MJ4: 11867.23 | MK4: 23.6 | ML4: 0 | MM4: 0 | MN4: 0 | MO4: 0 | MP4: 2587.64 | MQ4: 0 | MR4: 0 | MS4: 17618.51 | MT4: =MW4-MS4 -> 0 | MU4: 1118 | MV4: MOVE S320 | MW4: =SUM(MI4:MR4) -> 17618.51 | MX4: 261.38 | MY4: 4357.14 | MZ4: 1.51 | NA4: 0 | NB4: 0 | NC4: 0 | ND4: 0 | NE4: 179.69 | NF4: 0 | NG4: 0 | NH4: =SUM(MX4:NG4) -> 4799.72 | NK4: =(MS4/$N$116)*0 -> 0 | NL4: =(MT4/$O$116)*13804.26 -> 0 | NM4: =52000/60 -> 866.66667 | NN4: 20 | NP4: 5 | NQ4: =NQ$3 -> 469.6789 | NS4: =SUM(NI4:NR4) -> 1361.3456 | NT4: =78812.25/109 -> 723.04817 | NV4: =(NT4+NU4)*30% -> 216.91445 | NW4: =SUM(NT4:NV4) -> 939.96261 | NX4: =NS4+NW4 -> 2301.3082 | NY4: =NH4-NX4 -> 2498.4118 | NZ4: 2807.67 | OA4: 11656.4 | OB4: 0 | OC4: 0 | OD4: 0 | OE4: 0 | OF4: 0 | OG4: 2302.7 | OH4: 0 | OI4: 0 | OJ4: 16766.77 | OK4: =ON4-OJ4 -> 0 | OL4: 1122 | OM4: MOVE S320 | ON4: =SUM(NZ4:OI4) -> 16766.77 | OO4: 233.71 | OP4: 4357.14 | OQ4: 0 | OR4: 0 | OS4: 0 | OT4: 0 | OU4: 0 | OV4: 159.84 | OW4: 0 | OX4: 0 | OY4: =SUM(OO4:OX4) -> 4750.69 | PB4: =(OJ4/$OJ$116)*56307.47 -> 362.55224 | PC4: =(OK4/$O$116)*16757.91 -> 0 | PD4: =52000/60 -> 866.66667 | PE4: 20 | PF4: =3288/100 -> 32.88 | PG4: 5 | PH4: =PH$3 -> 495.20491 | PJ4: =SUM(OZ4:PI4) -> 1782.3038 | PK4: =PK$3 -> 643.25573 | PM4: =(PK4+PL4)*30% -> 192.97672 | PN4: =SUM(PK4:PM4) -> 836.23245 | PO4: =PJ4+PN4 -> 2618.5363 | PP4: =OY4-PO4 -> 2132.1537 | PQ4: 3194.22 | PR4: 9621.9 | PS4: 0 | PT4: 0 | PU4: 0 | PV4: 0 | PW4: 0 | PX4: 2130.72 | PY4: 0 | PZ4: 0 | QA4: 14946.84 | QB4: =QE4-QA4 -> 0 | QC4: 1000 | QD4: MOVE S320 | QE4: =SUM(PQ4:PZ4) -> 14946.84 | QF4: 265.88 | QG4: 4357.14 | QH4: 0 | QI4: 0 | QJ4: 0 | QK4: 0 | QL4: 0 | QM4: 147.96 | QN4: 0 | QO4: 0 | QP4: =SUM(QF4:QO4) -> 4770.98 | QS4: =(QA4/$QA$116)*27743.06 -> 175.70019 | QT4: =(QB4/$O$116)*10429.01 -> 0 | QU4: =52000/60 -> 866.66667 | QV4: 20 | QW4: =2074.8/110 -> 18.861818 | QX4: 5 | QY4: =QY$3 -> 428.14773 | RA4: =SUM(QQ4:QZ4) -> 1514.3764 | RB4: =68119.05/110 -> 619.26409 | RD4: =(RB4+RC4)*30% -> 185.77923 | RE4: =SUM(RB4:RD4) -> 805.04332 | RF4: =RA4+RE4 -> 2319.4197 | RG4: =QP4-RF4 -> 2451.5603 | RH4: 3073.98 | RI4: 9290.41 | RJ4: 11.19 | RK4: 0 | RL4: 0 | RM4: 0 | RN4: 0 | RO4: 3264.45 | RP4: 0 | RQ4: 0 | RR4: 15640.03 | RS4: =RV4-RR4 -> 0 | RT4: 1056 | RU4: MOVE S320 | RV4: =SUM(RH4:RQ4) -> 15640.03 | RW4: 255.88 | RX4: 4357.14 | RY4: 0.71 | RZ4: 0 | SA4: 0 | SB4: 0 | SC4: 0 | SD4: 226.7 | SE4: 0 | SF4: 0 | SG4: 4840.43 | SJ4: =(RR4/$RR$116)*25115.94 -> 153.69311 | SK4: =(RS4/$O$116)*12319.54 -> 0 | SL4: =52000/60 -> 866.66667 | SM4: 20 | SN4: =56040/113 -> 495.9292 | SO4: 5 | SP4: =SP$3 -> 428.52876 | SR4: =SUM(SH4:SQ4) -> 1969.8177 | SS4: =SS$3 -> 596.28469 | SU4: =(SS4+ST4)*30% -> 178.88541 | SV4: =SUM(SS4:SU4) -> 775.1701 | SW4: =SR4+SV4 -> 2744.9878 | SX4: =SG4-SW4 -> 2095.4422 | SY4: =Q4+BH4+CY4+EP4+GG4+HX4+JO4+LF4+MW4+ON4+QE4+RV4 -> 203867.18 | SZ4: =AB4+BS4+DJ4+FA4+GR4+II4+JZ4+LQ4+NH4+OY4+QP4+SG4 -> 57719.74 | TA4: =AR4+CI4+DZ4+FQ4+HH4+IY4+KP4+MG4+NX4+PO4+RF4+SW4 -> 26932.611 | TB4: =SZ4-TA4 -> 30787.129
A5: 1103 | B5: 1103_Wroc_GL | C5: MOVE S320 | D5: 5068.1 | E5: 4329.42 | F5: 0 | G5: 0 | H5: 0 | I5: 0 | J5: 0 | K5: 13349.66 | L5: 0 | M5: 0 | N5: 22747.18 | O5: =Q5-N5 -> 0 | P5: 1362 | Q5: =SUM(D5:M5) -> 22747.18 | R5: 421.87 | S5: 4357.14 | T5: 0 | U5: 0 | V5: 0 | W5: 0 | X5: 0 | Y5: 500 | Z5: 0 | AA5: 0 | AB5: =SUM(R5:AA5) -> 5279.01 | AE5: =(N5/$N$116)*21028.32 -> 247.32549 | AF5: =(O5/$O$116)*15324.97 -> 0 | AH5: 20 | AJ5: 5 | AK5: =39081.75/95 -> 411.38684 | AM5: =SUM(AC5:AL5) -> 683.71233 | AN5: =61284.58/95 -> 645.10084 | AO5: 0 | AP5: =(AN5+AO5)*30% -> 193.53025 | AQ5: =SUM(AN5:AP5) -> 838.63109 | AR5: =AM5+AQ5 -> 1522.3434 | AS5: =AB5-AR5 -> 3756.6666 | AT5: 5822.44 | AU5: 4524.2 | AV5: 23.2 | AW5: 0 | AX5: 0 | AY5: 0 | AZ5: 0 | BA5: 11449.43 | BB5: 0 | BC5: 0 | BD5: 21819.27 | BE5: =BH5-BD5 -> 0 | BF5: 1201 | BG5: MOVE S320 | BH5: =SUM(AT5:BC5) -> 21819.27 | BI5: 484.67 | BJ5: 4357.14 | BK5: 1.48 | BL5: 0 | BM5: 0 | BN5: 0 | BO5: 0 | BP5: 500 | BQ5: 0 | BR5: 0 | BS5: =SUM(BI5:BR5) -> 5343.29 | BV5: =(BD5/$BD$116)*21083.85 -> 239.30754 | BW5: =(BE5/$O$116)*12925.76 -> 0 | BY5: 20 | CA5: 5 | CB5: =37537.5/96 -> 391.01562 | CD5: =SUM(BT5:CC5) -> 655.32316 | CE5: =63860.36/96 -> 665.21208 | CG5: =(CE5+CF5)*30% -> 199.56363 | CH5: =SUM(CE5:CG5) -> 864.77571 | CI5: =CD5+CH5 -> 1520.0989 | CJ5: =BS5-CI5 -> 3823.1911 | CK5: 5281.5 | CL5: 4108.62 | CM5: 51.98 | CN5: 0 | CO5: 0 | CP5: 0 | CQ5: 0 | CR5: 12765.15 | CS5: 0 | CT5: 0 | CU5: 22207.25 | CV5: =CY5-CU5 -> 0 | CW5: 1321 | CX5: MOVE S320 | CY5: =SUM(CK5:CT5) -> 22207.25 | CZ5: 439.65 | DA5: 4357.14 | DB5: 3.32 | DC5: 0 | DD5: 0 | DE5: 0 | DF5: 0 | DG5: 500 | DH5: 0 | DI5: 0 | DJ5: =SUM(CZ5:DI5) -> 5300.11 | DM5: =(CU5/$CU$116)*24055.75 -> 241.42384 | DN5: =(CV5/$O$116)*16258.02 -> 0 | DP5: 20 | DR5: 5 | DS5: =DS$3 -> 428.4697 | DU5: =SUM(DK5:DT5) -> 694.89354 | DV5: =DV$3 -> 596.35071 | DX5: =(DV5+DW5)*30% -> 178.90521 | DY5: =SUM(DV5:DX5) -> 775.25592 | DZ5: =DU5+DY5 -> 1470.1495 | EA5: =DJ5-DZ5 -> 3829.9605 | EB5: 5279.64 | EC5: 8643.66 | ED5: 0 | EE5: 0 | EF5: 0 | EG5: 0 | EH5: 0 | EI5: 20899.29 | EJ5: 10.5 | EK5: 0 | EL5: 34833.09 | EM5: =EP5-EL5 -> 0 | EN5: 2218 | EO5: MOVE S320 | EP5: =SUM(EB5:EK5) -> 34833.09 | EQ5: 439.48 | ER5: 4357.14 | ES5: 0 | ET5: 0 | EU5: 0 | EV5: 0 | EW5: 0 | EX5: 500 | EY5: 0.58 | EZ5: 0 | FA5: =SUM(EQ5:EZ5) -> 5297.2 | FD5: =(EL5/$EL$116)*26325.65 -> 388.80872 | FE5: =(EM5/$O$116)*14846.27 -> 0 | FF5: =52000/60 -> 866.66667 | FG5: 20 | FH5: =14375.2/102 -> 140.93333 | FI5: 5 | FJ5: =FJ$3 -> 424.6802 | FL5: =SUM(FB5:FK5) -> 1846.0889 | FM5: =FM$3 -> 664.41902 | FO5: =(FM5+FN5)*30% -> 199.32571 | FP5: =SUM(FM5:FO5) -> 863.74473 | FQ5: =FL5+FP5 -> 2709.8336 | FR5: =FA5-FQ5 -> 2587.3664 | FS5: 6749.64 | FT5: 8207.12 | FU5: 12.5 | FV5: 0 | FW5: 0 | FX5: 0 | FY5: 0 | FZ5: 23446.82 | GA5: 9.5 | GB5: 0 | GC5: 38425.58 | GD5: =GG5-GC5 -> 0 | GE5: 2447 | GF5: MOVE S320 | GG5: =SUM(FS5:GB5) -> 38425.58 | GH5: 561.84 | GI5: 4357.14 | GJ5: 0.8 | GK5: 0 | GL5: 0 | GM5: 0 | GN5: 0 | GO5: 500 | GP5: 0.53 | GQ5: 0 | GR5: =SUM(GH5:GQ5) -> 5420.31 | GU5: =(GC5/$GC$116)*30198.86 -> 425.80325 | GV5: =(GD5/$O$116)*16844.27 -> 0 | GW5: =52000/60 -> 866.66667 | GX5: 20 | GY5: =18860.4/102 -> 184.90588 | GZ5: 5 | HA5: =HA$3 -> 358.47794 | HC5: =SUM(GS5:HB5) -> 1860.8537 | HD5: =HD$3 -> 866.9202 | HF5: =(HD5+HE5)*30% -> 260.07606 | HG5: =SUM(HD5:HF5) -> 1126.9963 | HH5: =HC5+HG5 -> 2987.85 | HI5: =GR5-HH5 -> 2432.46 | HJ5: 9014.14 | HK5: 10080.59 | HL5: 0 | HM5: 0 | HN5: 0 | HO5: 0 | HP5: 0 | HQ5: 25746.15 | HR5: 13.4 | HS5: 0 | HT5: 44854.28 | HU5: =HX5-HT5 -> 0 | HV5: 2817 | HW5: MOVE S320 | HX5: =SUM(HJ5:HS5) -> 44854.28 | HY5: 750.34 | HZ5: 4357.14 | IA5: 0 | IB5: 0 | IC5: 0 | ID5: 0 | IE5: 0 | IF5: 500 | IG5: 0.74 | IH5: 0 | II5: =SUM(HY5:IH5) -> 5608.22 | IL5: =(HT5/$HT$116)*31846.83 -> 496.87135 | IM5: =(HU5/$O$116)*17321.85 -> 0 | IN5: =52000/60 -> 866.66667 | IO5: 20 | IP5: =24366/105 -> 232.05714 | IQ5: 5 | IR5: =IR$3 -> 445.62857 | IT5: =SUM(IJ5:IS5) -> 2066.2237 | IU5: =IU$3 -> 538.79476 | IW5: =(IU5+IV5)*30% -> 161.63843 | IX5: =SUM(IU5:IW5) -> 700.43319 | IY5: =IT5+IX5 -> 2766.6569 | IZ5: =II5-IY5 -> 2841.5631 | JA5: 10188.03 | JB5: 11832.8 | JC5: 63.7 | JD5: 0 | JE5: 0 | JF5: 0 | JG5: 0 | JH5: 28091.9 | JI5: 5.7 | JJ5: 0 | JK5: 50182.13 | JL5: =JO5-JK5 -> 0 | JM5: 3028 | JN5: MOVE S320 | JO5: =SUM(JA5:JJ5) -> 50182.13 | JP5: 848.07 | JQ5: 4357.14 | JR5: 4.07 | JS5: 0 | JT5: 0 | JU5: 0 | JV5: 0 | JW5: 500 | JX5: 0.32 | JY5: 0 | JZ5: =SUM(JP5:JY5) -> 5709.6 | KC5: =(JK5/$N$116)*39010.72 -> 1012.2081 | KD5: =(JL5/$O$116)*19244.4 -> 0 | KE5: =52000/60 -> 866.66667 | KF5: 20 | KH5: 5 | KI5: =KI$3 -> 543.39953 | KK5: =SUM(KA5:KJ5) -> 2447.2743 | KL5: =KL$3 -> 497.32093 | KN5: =(KL5+KM5)*30% -> 149.19628 | KO5: =SUM(KL5:KN5) -> 646.51721 | KP5: =KK5+KO5 -> 3093.7915 | KQ5: =JZ5-KP5 -> 2615.8085 | KR5: 9228.85 | KS5: 10501.58 | KT5: 0 | KU5: 0 | KV5: 0 | KW5: 0 | KX5: 0 | KY5: 26614.04 | KZ5: 36.58 | LA5: 0 | LB5: 46381.05 | LC5: =LF5-LB5 -> 0 | LD5: 2696 | LE5: MOVE S320 | LF5: =SUM(KR5:LA5) -> 46381.05 | LG5: 768.23 | LH5: 4357.14 | LI5: 0 | LJ5: 0 | LK5: 0 | LL5: 0 | LM5: 0 | LN5: 500 | LO5: 2.03 | LP5: 0 | LQ5: =SUM(LG5:LP5) -> 5627.4 | LT5: =(LB5/$LB$116)*39133.48 -> 472.86074 | LU5: =(LC5/$O$116)*17015.75 -> 0 | LV5: =52000/60 -> 866.66667 | LW5: 20 | LY5: 5 | LZ5: =LZ$3 -> 508.03738 | MB5: =SUM(LR5:MA5) -> 1872.5648 | MC5: =MC$3 -> 593.54907 | ME5: =(MC5+MD5)*30% -> 178.06472 | MF5: =SUM(MC5:ME5) -> 771.61379 | MG5: =MB5+MF5 -> 2644.1786 | MH5: =LQ5-MG5 -> 2983.2214 | MI5: 6936.63 | MJ5: 6214.75 | MK5: 50.7 | ML5: 0 | MM5: 0 | MN5: 0 | MO5: 0 | MP5: 15366.45 | MQ5: 0 | MR5: 0 | MS5: 28568.53 | MT5: =MW5-MS5 -> 0 | MU5: 1719 | MV5: MOVE S320 | MW5: =SUM(MI5:MR5) -> 28568.53 | MX5: 577.42 | MY5: 4357.14 | MZ5: 3.24 | NA5: 0 | NB5: 0 | NC5: 0 | ND5: 0 | NE5: 500 | NF5: 0 | NG5: 0 | NH5: =SUM(MX5:NG5) -> 5437.8 | NK5: =(MS5/$N$116)*0 -> 0 | NL5: =(MT5/$O$116)*13804.26 -> 0 | NM5: =52000/60 -> 866.66667 | NN5: 20 | NP5: 5 | NQ5: =NQ$3 -> 469.6789 | NS5: =SUM(NI5:NR5) -> 1361.3456 | NT5: =78812.25/109 -> 723.04817 | NV5: =(NT5+NU5)*30% -> 216.91445 | NW5: =SUM(NT5:NV5) -> 939.96261 | NX5: =NS5+NW5 -> 2301.3082 | NY5: =NH5-NX5 -> 3136.4918 | NZ5: 6437.15 | OA5: 7662.91 | OB5: 18 | OC5: 0 | OD5: 0 | OE5: 0 | OF5: 0 | OG5: 18367.52 | OH5: 0 | OI5: 0 | OJ5: 32485.58 | OK5: =ON5-OJ5 -> 0 | OL5: 2002 | OM5: MOVE S320 | ON5: =SUM(NZ5:OI5) -> 32485.58 | OO5: 535.85 | OP5: 4357.14 | OQ5: 1.15 | OR5: 0 | OS5: 0 | OT5: 0 | OU5: 0 | OV5: 500 | OW5: 0 | OX5: 0 | OY5: =SUM(OO5:OX5) -> 5394.14 | PB5: =(OJ5/$OJ$116)*56307.47 -> 702.44417 | PC5: =(OK5/$O$116)*16757.91 -> 0 | PD5: =52000/60 -> 866.66667 | PE5: 20 | PF5: =3288/100 -> 32.88 | PG5: 5 | PH5: =PH$3 -> 495.20491 | PJ5: =SUM(OZ5:PI5) -> 2122.1957 | PK5: =PK$3 -> 643.25573 | PM5: =(PK5+PL5)*30% -> 192.97672 | PN5: =SUM(PK5:PM5) -> 836.23245 | PO5: =PJ5+PN5 -> 2958.4282 | PP5: =OY5-PO5 -> 2435.7118 | PQ5: 4546.76 | PR5: 6333.92 | PS5: 0 | PT5: 0 | PU5: 0 | PV5: 0 | PW5: 0 | PX5: 14688.9 | PY5: 0 | PZ5: 0 | QA5: 25569.58 | QB5: =QE5-QA5 -> 0 | QC5: 1647 | QD5: MOVE S320 | QE5: =SUM(PQ5:PZ5) -> 25569.58 | QF5: 378.49 | QG5: 4357.14 | QH5: 0 | QI5: 0 | QJ5: 0 | QK5: 0 | QL5: 0 | QM5: 500 | QN5: 0 | QO5: 0 | QP5: =SUM(QF5:QO5) -> 5235.63 | QS5: =(QA5/$QA$116)*27743.06 -> 300.57056 | QT5: =(QB5/$O$116)*10429.01 -> 0 | QU5: =52000/60 -> 866.66667 | QV5: 20 | QW5: =2074.8/110 -> 18.861818 | QX5: 5 | QY5: =QY$3 -> 428.14773 | RA5: =SUM(QQ5:QZ5) -> 1639.2468 | RB5: =68119.05/110 -> 619.26409 | RD5: =(RB5+RC5)*30% -> 185.77923 | RE5: =SUM(RB5:RD5) -> 805.04332 | RF5: =RA5+RE5 -> 2444.2901 | RG5: =QP5-RF5 -> 2791.3399 | RH5: 5909.12 | RI5: 6935.55 | RJ5: 0 | RK5: 0 | RL5: 0 | RM5: 0 | RN5: 0 | RO5: 18831.14 | RP5: 0 | RQ5: 0 | RR5: 31675.81 | RS5: =RV5-RR5 -> 0 | RT5: 1905 | RU5: MOVE S320 | RV5: =SUM(RH5:RQ5) -> 31675.81 | RW5: 491.88 | RX5: 4357.14 | RY5: 0 | RZ5: 0 | SA5: 0 | SB5: 0 | SC5: 0 | SD5: 500 | SE5: 0 | SF5: 0 | SG5: 5349.02 | SJ5: =(RR5/$RR$116)*25115.94 -> 311.27521 | SK5: =(RS5/$O$116)*12319.54 -> 0 | SL5: =52000/60 -> 866.66667 | SM5: 20 | SN5: =56040/113 -> 495.9292 | SO5: 5 | SP5: =SP$3 -> 428.52876 | SR5: =SUM(SH5:SQ5) -> 2127.3998 | SS5: =SS$3 -> 596.28469 | SU5: =(SS5+ST5)*30% -> 178.88541 | SV5: =SUM(SS5:SU5) -> 775.1701 | SW5: =SR5+SV5 -> 2902.5699 | SX5: =SG5-SW5 -> 2446.4501 | SY5: =Q5+BH5+CY5+EP5+GG5+HX5+JO5+LF5+MW5+ON5+QE5+RV5 -> 399749.33 | SZ5: =AB5+BS5+DJ5+FA5+GR5+II5+JZ5+LQ5+NH5+OY5+QP5+SG5 -> 65001.73 | TA5: =AR5+CI5+DZ5+FQ5+HH5+IY5+KP5+MG5+NX5+PO5+RF5+SW5 -> 29321.499 | TB5: =SZ5-TA5 -> 35680.231
A6: 1104 | B6: 1104_POZN_GL | C6: MOVE S320 | D6: 19593.64 | E6: 15001.6 | F6: 29041.47 | G6: 0 | H6: 0 | I6: 0 | J6: 0 | K6: 20 | L6: 0 | M6: 0 | N6: 63656.71 | O6: =Q6-N6 -> 0 | P6: 2890 | Q6: =SUM(D6:M6) -> 63656.71 | R6: 1630.96 | S6: 4357.14 | T6: 1855.24 | U6: 0 | V6: 0 | W6: 0 | X6: 0 | Y6: 1.39 | Z6: 0 | AA6: 0 | AB6: =SUM(R6:AA6) -> 7844.73 | AE6: =(N6/$N$116)*21028.32 -> 692.12655 | AF6: =(O6/$O$116)*15324.97 -> 0 | AH6: 20 | AJ6: 5 | AK6: =39081.75/95 -> 411.38684 | AM6: =SUM(AC6:AL6) -> 1128.5134 | AN6: =61284.58/95 -> 645.10084 | AO6: 0 | AP6: =(AN6+AO6)*30% -> 193.53025 | AQ6: =SUM(AN6:AP6) -> 838.63109 | AR6: =AM6+AQ6 -> 1967.1445 | AS6: =AB6-AR6 -> 5877.5855 | AT6: 23181.8 | AU6: 17692.09 | AV6: 38843.4 | AW6: 0 | AX6: 0 | AY6: 0 | AZ6: 0 | BA6: 150.5 | BB6: 0 | BC6: 0 | BD6: 79867.79 | BE6: =BH6-BD6 -> 0 | BF6: 3553 | BG6: MOVE S320 | BH6: =SUM(AT6:BC6) -> 79867.79 | BI6: 1929.63 | BJ6: 4357.14 | BK6: 2480.81 | BL6: 0 | BM6: 0 | BN6: 0 | BO6: 0 | BP6: 10.45 | BQ6: 0 | BR6: 0 | BS6: =SUM(BI6:BR6) -> 8778.03 | BV6: =(BD6/$BD$116)*21083.85 -> 875.96718 | BW6: =(BE6/$O$116)*12925.76 -> 0 | BY6: 20 | CA6: 5 | CB6: =37537.5/96 -> 391.01562 | CD6: =SUM(BT6:CC6) -> 1291.9828 | CE6: =63860.36/96 -> 665.21208 | CG6: =(CE6+CF6)*30% -> 199.56363 | CH6: =SUM(CE6:CG6) -> 864.77571 | CI6: =CD6+CH6 -> 2156.7585 | CJ6: =BS6-CI6 -> 6621.2715 | CK6: 30296.94 | CL6: 18980.41 | CM6: 39562.45 | CN6: 0 | CO6: 0 | CP6: 0 | CQ6: 0 | CR6: 12.5 | CS6: 9.5 | CT6: 0 | CU6: 88861.8 | CV6: =CY6-CU6 -> 0 | CW6: 3916 | CX6: MOVE S320 | CY6: =SUM(CK6:CT6) -> 88861.8 | CZ6: 2521.88 | DA6: 4357.14 | DB6: 2527.27 | DC6: 0 | DD6: 0 | DE6: 0 | DF6: 0 | DG6: 0.87 | DH6: 0.53 | DI6: 0 | DJ6: =SUM(CZ6:DI6) -> 9407.69 | DM6: =(CU6/$CU$116)*24055.75 -> 966.05196 | DN6: =(CV6/$O$116)*16258.02 -> 0 | DP6: 20 | DR6: 5 | DS6: =DS$3 -> 428.4697 | DU6: =SUM(DK6:DT6) -> 1419.5217 | DV6: =DV$3 -> 596.35071 | DX6: =(DV6+DW6)*30% -> 178.90521 | DY6: =SUM(DV6:DX6) -> 775.25592 | DZ6: =DU6+DY6 -> 2194.7776 | EA6: =DJ6-DZ6 -> 7212.9124 | EB6: 33798.17 | EC6: 21952.12 | ED6: 39975.22 | EE6: 0 | EF6: 0 | EG6: 0 | EH6: 0 | EI6: 20.98 | EJ6: 8.38 | EK6: 0 | EL6: 95754.87 | EM6: =EP6-EL6 -> 0 | EN6: 4074 | EO6: MOVE S320 | EP6: =SUM(EB6:EK6) -> 95754.87 | EQ6: 2813.35 | ER6: 4357.14 | ES6: 2553.83 | ET6: 0 | EU6: 0 | EV6: 0 | EW6: 0 | EX6: 1.46 | EY6: 0.47 | EZ6: 0 | FA6: =SUM(EQ6:EZ6) -> 9726.25 | FD6: =(EL6/$EL$116)*26325.65 -> 1068.8207 | FE6: =(EM6/$O$116)*14846.27 -> 0 | FF6: =52000/60 -> 866.66667 | FG6: 20 | FH6: =14375.2/102 -> 140.93333 | FI6: 5 | FJ6: =FJ$3 -> 424.6802 | FL6: =SUM(FB6:FK6) -> 2526.1009 | FM6: =FM$3 -> 664.41902 | FO6: =(FM6+FN6)*30% -> 199.32571 | FP6: =SUM(FM6:FO6) -> 863.74473 | FQ6: =FL6+FP6 -> 3389.8457 | FR6: =FA6-FQ6 -> 6336.4043 | FS6: 38062.77 | FT6: 26012.15 | FU6: 49080 | FV6: 0 | FW6: 0 | FX6: 0 | FY6: 0 | FZ6: 82.9 | GA6: 0 | GB6: 0 | GC6: 113237.82 | GD6: =GG6-GC6 -> 0 | GE6: 4576 | GF6: MOVE S320 | GG6: =SUM(FS6:GB6) -> 113237.82 | GH6: 3168.34 | GI6: 4357.14 | GJ6: 3135.13 | GK6: 0 | GL6: 0 | GM6: 0 | GN6: 0 | GO6: 5.76 | GP6: 0 | GQ6: 0 | GR6: =SUM(GH6:GQ6) -> 10666.37 | GU6: =(GC6/$GC$116)*30198.86 -> 1254.816 | GV6: =(GD6/$O$116)*16844.27 -> 0 | GW6: =52000/60 -> 866.66667 | GX6: 20 | GY6: =18860.4/102 -> 184.90588 | GZ6: 5 | HA6: =HA$3 -> 358.47794 | HC6: =SUM(GS6:HB6) -> 2689.8665 | HD6: =HD$3 -> 866.9202 | HF6: =(HD6+HE6)*30% -> 260.07606 | HG6: =SUM(HD6:HF6) -> 1126.9963 | HH6: =HC6+HG6 -> 3816.8627 | HI6: =GR6-HH6 -> 6849.5073 | HJ6: 51202.69 | HK6: 27883.61 | HL6: 53104.79 | HM6: 0 | HN6: 16.94 | HO6: 0 | HP6: 0 | HQ6: 82.2 | HR6: 0 | HS6: 0 | HT6: 132290.23 | HU6: =HX6-HT6 -> 0 | HV6: 5105 | HW6: MOVE S320 | HX6: =SUM(HJ6:HS6) -> 132290.23 | HY6: 4262.12 | HZ6: 4357.14 | IA6: 3392.33 | IB6: 0 | IC6: 1.1 | ID6: 0 | IE6: 0 | IF6: 5.71 | IG6: 0 | IH6: 0 | II6: =SUM(HY6:IH6) -> 12018.4 | IL6: =(HT6/$HT$116)*31846.83 -> 1465.4393 | IM6: =(HU6/$O$116)*17321.85 -> 0 | IN6: =52000/60 -> 866.66667 | IO6: 20 | IP6: =24366/105 -> 232.05714 | IQ6: 5 | IR6: =IR$3 -> 445.62857 | IT6: =SUM(IJ6:IS6) -> 3034.7917 | IU6: =IU$3 -> 538.79476 | IW6: =(IU6+IV6)*30% -> 161.63843 | IX6: =SUM(IU6:IW6) -> 700.43319 | IY6: =IT6+IX6 -> 3735.2249 | IZ6: =II6-IY6 -> 8283.1751 | JA6: 48144.6 | JB6: 26704.36 | JC6: 55036.03 | JD6: 0 | JE6: 12 | JF6: 0 | JG6: 0 | JH6: 35.81 | JI6: 0 | JJ6: 0 | JK6: 129932.8 | JL6: =JO6-JK6 -> 0 | JM6: 4853 | JN6: MOVE S320 | JO6: =SUM(JA6:JJ6) -> 129932.8 | JP6: 4007.58 | JQ6: 4357.14 | JR6: 3515.46 | JS6: 0 | JT6: 0.78 | JU6: 0 | JV6: 0 | JW6: 2.49 | JX6: 0 | JY6: 0 | JZ6: =SUM(JP6:JY6) -> 11883.45 | KC6: =(JK6/$N$116)*39010.72 -> 2620.8339 | KD6: =(JL6/$O$116)*19244.4 -> 0 | KE6: =52000/60 -> 866.66667 | KF6: 20 | KH6: 5 | KI6: =KI$3 -> 543.39953 | KK6: =SUM(KA6:KJ6) -> 4055.9001 | KL6: =KL$3 -> 497.32093 | KN6: =(KL6+KM6)*30% -> 149.19628 | KO6: =SUM(KL6:KN6) -> 646.51721 | KP6: =KK6+KO6 -> 4702.4173 | KQ6: =JZ6-KP6 -> 7181.0327 | KR6: 44337.04 | KS6: 28952.16 | KT6: 50580.42 | KU6: 0 | KV6: 17.66 | KW6: 0 | KX6: 0 | KY6: 53.7 | KZ6: 0 | LA6: 0 | LB6: 123940.98 | LC6: =LF6-LB6 -> 0 | LD6: 4609 | LE6: MOVE S320 | LF6: =SUM(KR6:LA6) -> 123940.98 | LG6: 3690.62 | LH6: 4357.14 | LI6: 3230.57 | LJ6: 0 | LK6: 1.14 | LL6: 0 | LM6: 0 | LN6: 3.73 | LO6: 0 | LP6: 0 | LQ6: =SUM(LG6:LP6) -> 11283.2 | LT6: =(LB6/$LB$116)*39133.48 -> 1263.5941 | LU6: =(LC6/$O$116)*17015.75 -> 0 | LV6: =52000/60 -> 866.66667 | LW6: 20 | LY6: 5 | LZ6: =LZ$3 -> 508.03738 | MB6: =SUM(LR6:MA6) -> 2663.2982 | MC6: =MC$3 -> 593.54907 | ME6: =(MC6+MD6)*30% -> 178.06472 | MF6: =SUM(MC6:ME6) -> 771.61379 | MG6: =MB6+MF6 -> 3434.912 | MH6: =LQ6-MG6 -> 7848.288 | MI6: 28175.47 | MJ6: 20655.24 | MK6: 37457.45 | ML6: 0 | MM6: 0 | MN6: 0 | MO6: 0 | MP6: 36.1 | MQ6: 0 | MR6: 87.34 | MS6: 86411.6 | MT6: =MW6-MS6 -> 0 | MU6: 3648 | MV6: MOVE S320 | MW6: =SUM(MI6:MR6) -> 86411.6 | MX6: 2345.35 | MY6: 4357.14 | MZ6: 2392.52 | NA6: 0 | NB6: 0 | NC6: 0 | ND6: 0 | NE6: 2.51 | NF6: 0 | NG6: 4.85 | NH6: =SUM(MX6:NG6) -> 9102.37 | NK6: =(MS6/$N$116)*0 -> 0 | NL6: =(MT6/$O$116)*13804.26 -> 0 | NM6: =52000/60 -> 866.66667 | NN6: 20 | NP6: 5 | NQ6: =NQ$3 -> 469.6789 | NS6: =SUM(NI6:NR6) -> 1361.3456 | NT6: =78812.25/109 -> 723.04817 | NV6: =(NT6+NU6)*30% -> 216.91445 | NW6: =SUM(NT6:NV6) -> 939.96261 | NX6: =NS6+NW6 -> 2301.3082 | NY6: =NH6-NX6 -> 6801.0618 | NZ6: 30080.03 | OA6: 20011.16 | OB6: 43390.64 | OC6: 0 | OD6: 0 | OE6: 0 | OF6: 0 | OG6: 28.16 | OH6: 0 | OI6: 157.86 | OJ6: 93667.85 | OK6: =ON6-OJ6 -> 0 | OL6: 4078 | OM6: MOVE S320 | ON6: =SUM(NZ6:OI6) -> 93667.85 | OO6: 2503.88 | OP6: 4357.14 | OQ6: 2772.11 | OR6: 0 | OS6: 0 | OT6: 0 | OU6: 0 | OV6: 1.96 | OW6: 0 | OX6: 8.77 | OY6: =SUM(OO6:OX6) -> 9643.86 | PB6: =(OJ6/$OJ$116)*56307.47 -> 2025.4044 | PC6: =(OK6/$O$116)*16757.91 -> 0 | PD6: =52000/60 -> 866.66667 | PE6: 20 | PF6: =3288/100 -> 32.88 | PG6: 5 | PH6: =PH$3 -> 495.20491 | PJ6: =SUM(OZ6:PI6) -> 3445.1559 | PK6: =PK$3 -> 643.25573 | PM6: =(PK6+PL6)*30% -> 192.97672 | PN6: =SUM(PK6:PM6) -> 836.23245 | PO6: =PJ6+PN6 -> 4281.3884 | PP6: =OY6-PO6 -> 5362.4716 | PQ6: 25867.89 | PR6: 16386.24 | PS6: 37135.75 | PT6: 0 | PU6: 0 | PV6: 0 | PW6: 0 | PX6: 14.5 | PY6: 0 | PZ6: 504.45 | QA6: 79908.83 | QB6: =QE6-QA6 -> 0 | QC6: 3371 | QD6: MOVE S320 | QE6: =SUM(PQ6:PZ6) -> 79908.83 | QF6: 2153.26 | QG6: 4357.14 | QH6: 2372.46 | QI6: 0 | QJ6: 0 | QK6: 0 | QL6: 0 | QM6: 1.01 | QN6: 0 | QO6: 28.02 | QP6: =SUM(QF6:QO6) -> 8911.89 | QS6: =(QA6/$QA$116)*27743.06 -> 939.32877 | QT6: =(QB6/$O$116)*10429.01 -> 0 | QU6: =52000/60 -> 866.66667 | QV6: 20 | QW6: =2074.8/110 -> 18.861818 | QX6: 5 | QY6: =QY$3 -> 428.14773 | RA6: =SUM(QQ6:QZ6) -> 2278.005 | RB6: =68119.05/110 -> 619.26409 | RD6: =(RB6+RC6)*30% -> 185.77923 | RE6: =SUM(RB6:RD6) -> 805.04332 | RF6: =RA6+RE6 -> 3083.0483 | RG6: =QP6-RF6 -> 5828.8417 | RH6: 27450.72 | RI6: 17975.59 | RJ6: 37929.34 | RK6: 0 | RL6: 0 | RM6: 0 | RN6: 0 | RO6: 48.56 | RP6: 0 | RQ6: 495.07 | RR6: 83899.28 | RS6: =RV6-RR6 -> 0 | RT6: 3408 | RU6: MOVE S320 | RV6: =SUM(RH6:RQ6) -> 83899.28 | RW6: 2285.02 | RX6: 4357.14 | RY6: 2423.03 | RZ6: 0 | SA6: 0 | SB6: 0 | SC6: 0 | SD6: 3.37 | SE6: 0 | SF6: 27.5 | SG6: 9068.56 | SJ6: =(RR6/$RR$116)*25115.94 -> 824.47034 | SK6: =(RS6/$O$116)*12319.54 -> 0 | SL6: =52000/60 -> 866.66667 | SM6: 20 | SN6: =56040/113 -> 495.9292 | SO6: 5 | SP6: =SP$3 -> 428.52876 | SR6: =SUM(SH6:SQ6) -> 2640.595 | SS6: =SS$3 -> 596.28469 | SU6: =(SS6+ST6)*30% -> 178.88541 | SV6: =SUM(SS6:SU6) -> 775.1701 | SW6: =SR6+SV6 -> 3415.7651 | SX6: =SG6-SW6 -> 5652.7949 | SY6: =Q6+BH6+CY6+EP6+GG6+HX6+JO6+LF6+MW6+ON6+QE6+RV6 -> 1171430.6 | SZ6: =AB6+BS6+DJ6+FA6+GR6+II6+JZ6+LQ6+NH6+OY6+QP6+SG6 -> 118334.8 | TA6: =AR6+CI6+DZ6+FQ6+HH6+IY6+KP6+MG6+NX6+PO6+RF6+SW6 -> 38479.453 | TB6: =SZ6-TA6 -> 79855.347
A7: 1105 | B7: 1105_SWINOU | C7: MOVE S320 | D7: 3013.93 | E7: 5953 | F7: 0 | G7: 0 | H7: 0 | I7: 0 | J7: 0 | K7: 0 | L7: 0 | M7: 0 | N7: 8966.93 | O7: =Q7-N7 -> 0 | P7: 424 | Q7: =SUM(D7:M7) -> 8966.93 | R7: 250.87 | S7: 4357.14 | T7: 0 | U7: 0 | V7: 0 | W7: 0 | X7: 0 | Y7: 0 | Z7: 0 | AA7: 0 | AB7: =SUM(R7:AA7) -> 4608.01 | AE7: =(N7/$N$116)*21028.32 -> 97.495618 | AF7: =(O7/$O$116)*15324.97 -> 0 | AH7: 20 | AJ7: 5 | AK7: =39081.75/95 -> 411.38684 | AM7: =SUM(AC7:AL7) -> 533.88246 | AN7: =61284.58/95 -> 645.10084 | AO7: 0 | AP7: =(AN7+AO7)*30% -> 193.53025 | AQ7: =SUM(AN7:AP7) -> 838.63109 | AR7: =AM7+AQ7 -> 1372.5136 | AS7: =AB7-AR7 -> 3235.4964 | AT7: 3170.44 | AU7: 5430.52 | AV7: 0 | AW7: 0 | AX7: 0 | AY7: 0 | AZ7: 0 | BA7: 0 | BB7: 0 | BC7: 0 | BD7: 8600.96 | BE7: =BH7-BD7 -> 0 | BF7: 386 | BG7: MOVE S320 | BH7: =SUM(AT7:BC7) -> 8600.96 | BI7: 263.91 | BJ7: 4357.14 | BK7: 0 | BL7: 0 | BM7: 0 | BN7: 0 | BO7: 0 | BP7: 0 | BQ7: 0 | BR7: 0 | BS7: =SUM(BI7:BR7) -> 4621.05 | BV7: =(BD7/$BD$116)*21083.85 -> 94.33288 | BW7: =(BE7/$O$116)*12925.76 -> 0 | BY7: 20 | CA7: 5 | CB7: =37537.5/96 -> 391.01562 | CD7: =SUM(BT7:CC7) -> 510.3485 | CE7: =63860.36/96 -> 665.21208 | CG7: =(CE7+CF7)*30% -> 199.56363 | CH7: =SUM(CE7:CG7) -> 864.77571 | CI7: =CD7+CH7 -> 1375.1242 | CJ7: =BS7-CI7 -> 3245.9258 | CK7: 4629.64 | CL7: 6931.1 | CM7: 0 | CN7: 0 | CO7: 0 | CP7: 0 | CQ7: 0 | CR7: 0 | CS7: 0 | CT7: 0 | CU7: 11560.74 | CV7: =CY7-CU7 -> 0 | CW7: 482 | CX7: MOVE S320 | CY7: =SUM(CK7:CT7) -> 11560.74 | CZ7: 385.37 | DA7: 4357.14 | DB7: 0 | DC7: 0 | DD7: 0 | DE7: 0 | DF7: 0 | DG7: 0 | DH7: 0 | DI7: 0 | DJ7: =SUM(CZ7:DI7) -> 4742.51 | DM7: =(CU7/$CU$116)*24055.75 -> 125.6814 | DN7: =(CV7/$O$116)*16258.02 -> 0 | DP7: 20 | DR7: 5 | DS7: =DS$3 -> 428.4697 | DU7: =SUM(DK7:DT7) -> 579.1511 | DV7: =DV$3 -> 596.35071 | DX7: =(DV7+DW7)*30% -> 178.90521 | DY7: =SUM(DV7:DX7) -> 775.25592 | DZ7: =DU7+DY7 -> 1354.407 | EA7: =DJ7-DZ7 -> 3388.103 | EB7: 4119.21 | EC7: 7181.88 | ED7: 0 | EE7: 0 | EF7: 0 | EG7: 0 | EH7: 0 | EI7: 0 | EJ7: 0 | EK7: 0 | EL7: 11301.09 | EM7: =EP7-EL7 -> 0 | EN7: 482 | EO7: MOVE S320 | EP7: =SUM(EB7:EK7) -> 11301.09 | EQ7: 342.88 | ER7: 4357.14 | ES7: 0 | ET7: 0 | EU7: 0 | EV7: 0 | EW7: 0 | EX7: 0 | EY7: 0 | EZ7: 0 | FA7: =SUM(EQ7:EZ7) -> 4700.02 | FD7: =(EL7/$EL$116)*26325.65 -> 126.14334 | FE7: =(EM7/$O$116)*14846.27 -> 0 | FF7: =52000/60 -> 866.66667 | FG7: 20 | FH7: =14375.2/102 -> 140.93333 | FI7: 5 | FJ7: =FJ$3 -> 424.6802 | FL7: =SUM(FB7:FK7) -> 1583.4235 | FM7: =FM$3 -> 664.41902 | FO7: =(FM7+FN7)*30% -> 199.32571 | FP7: =SUM(FM7:FO7) -> 863.74473 | FQ7: =FL7+FP7 -> 2447.1683 | FR7: =FA7-FQ7 -> 2252.8517 | FS7: 5933.64 | FT7: 12111.8 | FU7: 0 | FV7: 0 | FW7: 0 | FX7: 0 | FY7: 0 | FZ7: 46.7 | GA7: 0 | GB7: 0 | GC7: 18092.14 | GD7: =GG7-GC7 -> 0 | GE7: 787 | GF7: MOVE S320 | GG7: =SUM(FS7:GB7) -> 18092.14 | GH7: 493.91 | GI7: 4357.14 | GJ7: 0 | GK7: 0 | GL7: 0 | GM7: 0 | GN7: 0 | GO7: 3.24 | GP7: 0 | GQ7: 0 | GR7: =SUM(GH7:GQ7) -> 4854.29 | GU7: =(GC7/$GC$116)*30198.86 -> 200.48343 | GV7: =(GD7/$O$116)*16844.27 -> 0 | GW7: =52000/60 -> 866.66667 | GX7: 20 | GY7: =18860.4/102 -> 184.90588 | GZ7: 5 | HA7: =HA$3 -> 358.47794 | HC7: =SUM(GS7:HB7) -> 1635.5339 | HD7: =HD$3 -> 866.9202 | HF7: =(HD7+HE7)*30% -> 260.07606 | HG7: =SUM(HD7:HF7) -> 1126.9963 | HH7: =HC7+HG7 -> 2762.5302 | HI7: =GR7-HH7 -> 2091.7598 | HJ7: 7500.38 | HK7: 13743.52 | HL7: 20.2 | HM7: 0 | HN7: 0 | HO7: 0 | HP7: 0 | HQ7: 13 | HR7: 0 | HS7: 0 | HT7: 21277.1 | HU7: =HX7-HT7 -> 0 | HV7: 881 | HW7: MOVE S320 | HX7: =SUM(HJ7:HS7) -> 21277.1 | HY7: 624.33 | HZ7: 4357.14 | IA7: 1.29 | IB7: 0 | IC7: 0 | ID7: 0 | IE7: 0 | IF7: 0.9 | IG7: 0 | IH7: 0 | II7: =SUM(HY7:IH7) -> 4983.66 | IL7: =(HT7/$HT$116)*31846.83 -> 235.69616 | IM7: =(HU7/$O$116)*17321.85 -> 0 | IN7: =52000/60 -> 866.66667 | IO7: 20 | IP7: =24366/105 -> 232.05714 | IQ7: 5 | IR7: =IR$3 -> 445.62857 | IT7: =SUM(IJ7:IS7) -> 1805.0485 | IU7: =IU$3 -> 538.79476 | IW7: =(IU7+IV7)*30% -> 161.63843 | IX7: =SUM(IU7:IW7) -> 700.43319 | IY7: =IT7+IX7 -> 2505.4817 | IZ7: =II7-IY7 -> 2478.1783 | JA7: 11780.08 | JB7: 16270.03 | JC7: 105.5 | JD7: 0 | JE7: 0 | JF7: 0 | JG7: 0 | JH7: 0 | JI7: 25.77 | JJ7: 0 | JK7: 28181.38 | JL7: =JO7-JK7 -> 0 | JM7: 1130 | JN7: MOVE S320 | JO7: =SUM(JA7:JJ7) -> 28181.38 | JP7: 980.58 | JQ7: 4357.14 | JR7: 6.74 | JS7: 0 | JT7: 0 | JU7: 0 | JV7: 0 | JW7: 0 | JX7: 1.43 | JY7: 0 | JZ7: =SUM(JP7:JY7) -> 5345.89 | KC7: =(JK7/$N$116)*39010.72 -> 568.43782 | KD7: =(JL7/$O$116)*19244.4 -> 0 | KE7: =52000/60 -> 866.66667 | KF7: 20 | KH7: 5 | KI7: =KI$3 -> 543.39953 | KK7: =SUM(KA7:KJ7) -> 2003.504 | KL7: =KL$3 -> 497.32093 | KN7: =(KL7+KM7)*30% -> 149.19628 | KO7: =SUM(KL7:KN7) -> 646.51721 | KP7: =KK7+KO7 -> 2650.0212 | KQ7: =JZ7-KP7 -> 2695.8688 | KR7: 10665.31 | KS7: 21097.43 | KT7: 11.6 | KU7: 0 | KV7: 0 | KW7: 0 | KX7: 0 | KY7: 0 | KZ7: 0 | LA7: 0 | LB7: 31774.34 | LC7: =LF7-LB7 -> 0 | LD7: 1287 | LE7: MOVE S320 | LF7: =SUM(KR7:LA7) -> 31774.34 | LG7: 887.79 | LH7: 4357.14 | LI7: 0.74 | LJ7: 0 | LK7: 0 | LL7: 0 | LM7: 0 | LN7: 0 | LO7: 0 | LP7: 0 | LQ7: =SUM(LG7:LP7) -> 5245.67 | LT7: =(LB7/$LB$116)*39133.48 -> 323.94346 | LU7: =(LC7/$O$116)*17015.75 -> 0 | LV7: =52000/60 -> 866.66667 | LW7: 20 | LY7: 5 | LZ7: =LZ$3 -> 508.03738 | MB7: =SUM(LR7:MA7) -> 1723.6475 | MC7: =MC$3 -> 593.54907 | ME7: =(MC7+MD7)*30% -> 178.06472 | MF7: =SUM(MC7:ME7) -> 771.61379 | MG7: =MB7+MF7 -> 2495.2613 | MH7: =LQ7-MG7 -> 2750.4087 | MI7: 4251.16 | MJ7: 13685.49 | MK7: 12.8 | ML7: 0 | MM7: 0 | MN7: 0 | MO7: 0 | MP7: 0 | MQ7: 0 | MR7: 0 | MS7: 17949.45 | MT7: =MW7-MS7 -> 0 | MU7: 764 | MV7: MOVE S320 | MW7: =SUM(MI7:MR7) -> 17949.45 | MX7: 353.87 | MY7: 4357.14 | MZ7: 0.82 | NA7: 0 | NB7: 0 | NC7: 0 | ND7: 0 | NE7: 0 | NF7: 0 | NG7: 0 | NH7: =SUM(MX7:NG7) -> 4711.83 | NK7: =(MS7/$N$116)*0 -> 0 | NL7: =(MT7/$O$116)*13804.26 -> 0 | NM7: =52000/60 -> 866.66667 | NN7: 20 | NP7: 5 | NQ7: =NQ$3 -> 469.6789 | NS7: =SUM(NI7:NR7) -> 1361.3456 | NT7: =78812.25/109 -> 723.04817 | NV7: =(NT7+NU7)*30% -> 216.91445 | NW7: =SUM(NT7:NV7) -> 939.96261 | NX7: =NS7+NW7 -> 2301.3082 | NY7: =NH7-NX7 -> 2410.5218 | NZ7: 3107.08 | OA7: 11487.18 | OB7: 0 | OC7: 0 | OD7: 0 | OE7: 0 | OF7: 0 | OG7: 0 | OH7: 0 | OI7: 0 | OJ7: 14594.26 | OK7: =ON7-OJ7 -> 0 | OL7: 620 | OM7: MOVE S320 | ON7: =SUM(NZ7:OI7) -> 14594.26 | OO7: 258.63 | OP7: 4357.14 | OQ7: 0 | OR7: 0 | OS7: 0 | OT7: 0 | OU7: 0 | OV7: 0 | OW7: 0 | OX7: 0 | OY7: =SUM(OO7:OX7) -> 4615.77 | PB7: =(OJ7/$OJ$116)*56307.47 -> 315.57549 | PC7: =(OK7/$O$116)*16757.91 -> 0 | PD7: =52000/60 -> 866.66667 | PE7: 20 | PF7: =3288/100 -> 32.88 | PG7: 5 | PH7: =PH$3 -> 495.20491 | PJ7: =SUM(OZ7:PI7) -> 1735.3271 | PK7: =PK$3 -> 643.25573 | PM7: =(PK7+PL7)*30% -> 192.97672 | PN7: =SUM(PK7:PM7) -> 836.23245 | PO7: =PJ7+PN7 -> 2571.5595 | PP7: =OY7-PO7 -> 2044.2105 | PQ7: 2007.91 | PR7: 8830.72 | PS7: 0 | PT7: 0 | PU7: 0 | PV7: 0 | PW7: 0 | PX7: 3 | PY7: 0 | PZ7: 21.8 | QA7: 10863.43 | QB7: =QE7-QA7 -> 0 | QC7: 464 | QD7: MOVE S320 | QE7: =SUM(PQ7:PZ7) -> 10863.43 | QF7: 167.13 | QG7: 4357.14 | QH7: 0 | QI7: 0 | QJ7: 0 | QK7: 0 | QL7: 0 | QM7: 0.21 | QN7: 0 | QO7: 1.21 | QP7: =SUM(QF7:QO7) -> 4525.69 | QS7: =(QA7/$QA$116)*27743.06 -> 127.69968 | QT7: =(QB7/$O$116)*10429.01 -> 0 | QU7: =52000/60 -> 866.66667 | QV7: 20 | QW7: =2074.8/110 -> 18.861818 | QX7: 5 | QY7: =QY$3 -> 428.14773 | RA7: =SUM(QQ7:QZ7) -> 1466.3759 | RB7: =68119.05/110 -> 619.26409 | RD7: =(RB7+RC7)*30% -> 185.77923 | RE7: =SUM(RB7:RD7) -> 805.04332 | RF7: =RA7+RE7 -> 2271.4192 | RG7: =QP7-RF7 -> 2254.2708 | RH7: 3311.71 | RI7: 8429.56 | RJ7: 12.95 | RK7: 0 | RL7: 0 | RM7: 0 | RN7: 0 | RO7: 0 | RP7: 0 | RQ7: 0 | RR7: 11754.22 | RS7: =RV7-RR7 -> 0 | RT7: 458 | RU7: MOVE S320 | RV7: =SUM(RH7:RQ7) -> 11754.22 | RW7: 275.67 | RX7: 4357.14 | RY7: 0.83 | RZ7: 0 | SA7: 0 | SB7: 0 | SC7: 0 | SD7: 0 | SE7: 0 | SF7: 0 | SG7: 4633.64 | SJ7: =(RR7/$RR$116)*25115.94 -> 115.50762 | SK7: =(RS7/$O$116)*12319.54 -> 0 | SL7: =52000/60 -> 866.66667 | SM7: 20 | SN7: =56040/113 -> 495.9292 | SO7: 5 | SP7: =SP$3 -> 428.52876 | SR7: =SUM(SH7:SQ7) -> 1931.6322 | SS7: =SS$3 -> 596.28469 | SU7: =(SS7+ST7)*30% -> 178.88541 | SV7: =SUM(SS7:SU7) -> 775.1701 | SW7: =SR7+SV7 -> 2706.8023 | SX7: =SG7-SW7 -> 1926.8377 | SY7: =Q7+BH7+CY7+EP7+GG7+HX7+JO7+LF7+MW7+ON7+QE7+RV7 -> 194916.04 | SZ7: =AB7+BS7+DJ7+FA7+GR7+II7+JZ7+LQ7+NH7+OY7+QP7+SG7 -> 57588.03 | TA7: =AR7+CI7+DZ7+FQ7+HH7+IY7+KP7+MG7+NX7+PO7+RF7+SW7 -> 26813.597 | TB7: =SZ7-TA7 -> 30774.433
